Workbook

Sheet portfolios
D1: Risk Matched Portfolio Optimizations
B2: Current Portfolio | C2: Return Matched | D2: Volatility | E2: Value at Risk | F2: Covid-19 Loss | G2: Volatility Parity
A3: Investment Grade Fixed Income | B3: 0.38 | C3: 0.47498843 | D3: 0.31240057 | E3: 0.31865737 | F3: 0.33582636 | G3: 1.348707
A4: US Short Duration Debt | B4: 18 | C4: 15.591247 | G4: 80.169914
A5: US Dollar Debt | B5: 20 | C5: 17.735691 | D5: 16.5 | E5: 16.5 | F5: 16.5 | G5: 31.440909
A6: US Inflation Protected Bonds | B6: 0 | C6: 9.3290826 | D6: 9.7290583 | E6: 10.14411 | F6: 11.280824 | G6: 11.914375
A7: US Corporate Bonds | B7: 0 | C7: 4.8428231 | D7: 5.0109982 | E7: 5.2216267 | F7: 5.8018122 | G7: 11.3455
A8: Other Fixed Income | C8: 0.056535337 | D8: 0.082281582 | E8: 0.081923102 | F8: 0.080961091 | G8: 0.082101686
A9: US High Yield | B9: 0 | C9: 3.8166767 | D9: 5.2245979 | E9: 5.2223728 | F9: 5.218057 | G9: 5.0270201
A10: EM External Debt | B10: 0 | C10: 1.836857 | D10: 3.0035603 | E10: 2.9699374 | F10: 2.8780521 | G10: 3.1831485
A11: Public Equity | B11: 0.46 | C11: 0.25577201 | D11: 0.36208468 | E11: 0.35460815 | F11: 0.33405453 | G11: 0.26418253
A12: Global Equities (ACWI) | B12: 10 | G12: 2.2059526
A13: US Equity | B13: =SUM(B14:B16) -> 11 | C13: =SUM(C14:C16) -> 10.225934 | D13: =SUM(D14:D16) -> 15.383443 | E13: =SUM(E14:E16) -> 15.073612 | F13: =SUM(F14:F16) -> 14.224785 | G13: =SUM(G14:G16) -> 6.5937643
A14: US Large Cap Growth Equity | B14: 6 | C14: 4.0903737 | D14: 6.1533771 | E14: 6.0294448 | F14: 5.6899141 | G14: 2.1504349
A15: US Large Cap Value Equity | B15: 5 | C15: 4.6016704 | D15: 6.9225492 | E15: 6.7831254 | F15: 6.4011533 | G15: 2.4559033
A16: US Small Cap Equity | B16: 0 | C16: 1.5338901 | D16: 2.3075164 | E16: 2.2610418 | F16: 2.1337178 | G16: 1.9874261
A17: Non-US Developed Equity | B17: 19 | C17: 11.523182 | D17: 14.344436 | E17: 14.021994 | F17: 13.129999 | G17: 9.3243049
A18: Europe ex-UK Equity | B18: 7 | C18: 3.1156243 | D18: 3.8412696 | E18: 3.7483718 | F18: 3.4917412 | G18: 2.2352623
A19: UK Equity | B19: 0 | C19: 3.9346941 | D19: 5.5842682 | E19: 5.480502 | F19: 5.1954634 | G19: 2.529089
A20: Japanese Equity | B20: 4 | C20: 1.4259238 | D20: 0.3805328 | E20: 0.35133085 | F20: 0.2665693 | G20: 2.4104074
A21: Asia-Pacific Equity | B21: 8 | C21: 3.0469396 | D21: 4.5383657 | E21: 4.4417894 | F21: 4.1762249 | G21: 2.1495462
A22: Emerging Market Equity | B22: 6 | C22: 2.1995207 | D22: 3.6141786 | E22: 3.5288961 | F22: 3.295083 | G22: 1.6766569
A23: Income Equity | B23: =B24+B25 -> 0 | C23: =C24+C25 -> 1.6285646 | D23: =D24+D25 -> 2.8664104 | E23: =E24+E25 -> 2.8363129 | F23: =F24+F25 -> 2.7555858 | G23: =G24+G25 -> 6.617574
A24: Global REITs | B24: 0 | C24: 0.81428232 | D24: 1.4332052 | E24: 1.4181564 | F24: 1.3777929 | G24: 3.3573158
A25: Infrastructure Equity | B25: 0 | C25: 0.81428232 | D25: 1.4332052 | E25: 1.4181564 | F25: 1.3777929 | G25: 3.2602582
A26: Hedge Funds | B26: 0.16 | C26: 0.1406057 | D26: 0.10576099 | E26: 0.10911835 | F26: 0.11824023 | G26: 0.30370531
A27: Multi-Strategy | B27: 16 | G27: 7.8339736
A28: Event Driven | B28: 0 | C28: 6.4650209 | D28: 3.11515 | E28: 3.3177644 | F28: 3.8671303 | G28: 6.670125
A29: Equity Long/Short | B29: 0 | C29: 3.3950685 | D29: 0.83678261 | E29: 0.8816167 | F29: 0.99552013 | G29: 4.2381812
A30: Tactical Trading | B30: 0 | C30: 4.2004811 | D30: 6.6241666 | E30: 6.7124543 | F30: 6.9613722 | G30: 11.628252
A31: Private Equity | C31: 0.032439582 | D31: 0.05605778 | E31: 0.055086113 | F31: 0.052444139 | G31: 0.066858028
A32: Buyout | B32: 0 | C32: 1.3283814 | D32: 2.3667726 | E32: 2.328963 | F32: 2.226511 | G32: 2.3863398
A33: Growth | B33: 0 | C33: 1.0588237 | D33: 1.8482071 | E33: 1.8157078 | F33: 1.727335 | G33: 2.1795848
A34: Venture | B34: 0 | C34: 0.85675317 | D34: 1.3907984 | E34: 1.3639404 | F34: 1.2905678 | G34: 2.1198782
A35: Other Private Assets | C35: 0.039658934 | D35: 0.081414396 | E35: 0.080606911 | F35: 0.078473652 | G35: 0.10660066
A36: Private Credit | B36: 0 | C36: 1.7787983 | D36: 3.5201129 | E36: 3.4885678 | F36: 3.4055878 | G36: 3.9331671
A37: Core Real Estate | B37: 0 | C37: 1.6403213 | D37: 3.465995 | E37: 3.4290925 | F37: 3.331333 | G37: 3.3366095
A38: Infrastructure | B38: 0 | C38: 0.54677378 | D38: 1.1553317 | E38: 1.1430308 | F38: 1.1104443 | G38: 3.3902898
A39: Cash, Money Markets and Deposits | G39: -1.1721552
A40: Leverage (SOFR + 1%) | B40: 0 | C40: 0 | D40: 0 | E40: 0 | F40: 0 | G40: -117.21552
...

Sheet risk_dashboard
B1: Current Portfolio | D1: Return Matched | F1: Volatility Matched | H1: VaR Matched | J1: Covid-19 Loss Matched | L1: Volatility Parity
A2: Investment Grade Fixed Income | B2: 0.38 | D2: 0.47498843 | F2: 0.31240057 | H2: 0.31865737 | J2: 0.33582636 | L2: 1.348707
A3: Other Fixed Income | B3: - | D3: 0.056535337 | F3: 0.082281582 | H3: 0.081923102 | J3: 0.080961091 | L3: 0.082101686
A4: Public Equity | B4: 0.46 | D4: 0.25577201 | F4: 0.36208468 | H4: 0.35460815 | J4: 0.33405453 | L4: 0.26418253
A5: Hedge Funds | B5: 0.16 | D5: 0.1406057 | F5: 0.10576099 | H5: 0.10911835 | J5: 0.11824023 | L5: 0.30370531
A6: Private Equity | B6: - | D6: 0.032439582 | F6: 0.05605778 | H6: 0.055086113 | J6: 0.052444139 | L6: 0.066858028
A7: Other Private Assets | B7: - | D7: 0.039658934 | F7: 0.081414396 | H7: 0.080606911 | J7: 0.078473652 | L7: 0.10660066
A8: Cash, Money Markets and Deposits | B8: - | D8: - | F8: - | H8: - | J8: - | L8: -1.1721552
A9: Estimated Mean Return | B9: 0.053990266 | D9: 0.053990266 | F9: 0.06466639 | H9: 0.064318022 | J9: 0.063368043 | L9: 0.055734392
A10: Sharpe Ratio | B10: 0.39333908 | D10: 0.53548994 | F10: 0.53819242 | H10: 0.54082562 | J10: 0.54841601 | L10: 0.41700333
A11: Volatility | B11: 0.073702989 | D11: 0.054137834 | F11: 0.073702989 | H11: 0.0727 | J11: 0.069961566 | L11: 0.073702989
A12: Factor Based Risk Analytics
A13: Predicted Performance Over Stress Periods | B13: Nominal | C13: Real | D13: Nominal | E13: Real | F13: Nominal | G13: Real | H13: Nominal | I13: Real | J13: Nominal | K13: Real | L13: Nominal | M13: Real
A14: Oil Embargo | B14: -0.14483801 | C14: -0.27328 | D14: -0.094594885 | E14: -0.2305832 | F14: -0.16092901 | G14: -0.2869542 | H14: -0.15793298 | I14: -0.28440816 | J14: -0.14965947 | K14: -0.27737729 | L14: -0.19697794 | M14: -0.31758872
A15: US Inflation / Iranian Revolution | B15: 0.14089278 | C15: -0.038581176 | D15: 0.096723861 | E15: -0.07580188 | F15: 0.088165337 | G15: -0.083014062 | H15: 0.087513047 | I15: -0.08356374 | J15: 0.085688203 | K15: -0.085101517 | L15: -0.0014015082 | M15: -0.15849114
A16: US Stagflation | B16: 0.033694949 | C16: -0.092473682 | D16: 0.11581362 | E16: -0.020378088 | F16: 0.071508031 | G16: -0.059275912 | H16: 0.074240357 | I16: -0.056877083 | J16: 0.081803676 | K16: -0.050236912 | L16: 0.061358362 | M16: -0.068186754
A17: Black Monday | B17: -0.092492094 | C17: -0.094866959 | D17: -0.057897347 | E17: -0.060362743 | F17: -0.083709867 | G17: -0.086107713 | H17: -0.082072068 | I17: -0.084474201 | J17: -0.077563783 | K17: -0.079977713 | L17: -0.063653087 | M17: -0.06610342
A18: Bond Crisis | B18: -0.018007909 | C18: -0.040952317 | D18: -0.01962272 | E18: -0.042529398 | F18: -0.030105244 | G18: -0.052766996 | H18: -0.029953102 | I18: -0.05261841 | J18: -0.029542505 | K18: -0.052217405 | L18: -0.069605047 | M18: -0.091343879
A19: Russian Default / LTCM Collapse | B19: -0.080106687 | C19: -0.081236174 | D19: -0.054207314 | E19: -0.055368601 | F19: -0.078490596 | G19: -0.079622067 | H19: -0.077204242 | I19: -0.078337292 | J19: -0.073669895 | K19: -0.074807285 | L19: -0.06818147 | M19: -0.069325599
A20: Tech Meltdown | B20: -0.19376491 | C20: -0.23746714 | D20: -0.061228857 | E20: -0.11211524 | F20: -0.10978879 | G20: -0.15804297 | H20: -0.1058343 | I20: -0.15430284 | J20: -0.094834377 | K20: -0.14389916 | L20: -0.088039768 | M20: -0.13747286
A21: Financial Crisis | B21: -0.27355461 | C21: -0.28556062 | D21: -0.19338441 | E21: -0.2067154 | F21: -0.27244817 | G21: -0.28447246 | H21: -0.26830809 | I21: -0.2804008 | J21: -0.25682898 | K21: -0.26911142 | L21: -0.25216868 | M21: -0.26452814
A22: Covid-19 | B22: -0.092205776 | C22: -0.08899225 | D22: -0.068168893 | E22: -0.064870278 | F22: -0.098189053 | G22: -0.094996708 | H22: -0.096593515 | I22: -0.093395521 | J22: -0.092205776 | K22: -0.08899225 | L22: -0.084503929 | M22: -0.081263139
A23: Value at Risk with 99% Confidence
A24: Over 1 Month | B24: 0.053102767 | D24: 0.040619679 | E24: 0.042649554 | F24: 0.056964289 | G24: 0.058959582 | H24: 0.056267112 | I24: 0.058263879 | J24: 0.054049205 | K24: 0.056050665 | L24: 0.058244202 | M24: 0.060236787
A25: Over 1 Year | B25: 0.17132123 | D25: 0.11595396 | E25: 0.138097 | F25: 0.17452332 | G25: 0.19477946 | H25: 0.17119431 | I25: 0.19174002 | J25: 0.1632222 | K25: 0.18335676 | L25: 0.17032207 | M25: 0.18970425
A26: Over 3 Years | B26: 0.19407783 | D26: 0.10041169 | E26: 0.15729489 | F26: 0.16412415 | G26: 0.21525979 | H26: 0.15987309 | I26: 0.21145922 | J26: 0.14812341 | K26: 0.20131319 | L26: 0.16951249 | M26: 0.22076961
A27: Conditional Value at Risk with 99% Confidence
A28: Over 1 Month | B28: 0.074840609 | C28: 0.076798078 | D28: 0.054161651 | E28: 0.056162873 | F28: 0.077167891 | G28: 0.079120437 | H28: 0.075982038 | I28: 0.077937092 | J28: 0.072729595 | K28: 0.074691531 | L28: 0.072082562 | M28: 0.074045867
A29: Over 1 Year | B29: 0.20927018 | C29: 0.22732157 | D29: 0.14333107 | E29: 0.16288138 | F29: 0.20819164 | G29: 0.2262859 | H29: 0.20479274 | I29: 0.22296503 | J29: 0.1954103 | K29: 0.21379859 | L29: 0.19757025 | M29: 0.2158984
A30: Over 3 Years | B30: 0.24381045 | C30: 0.29139846 | D30: 0.14362707 | E30: 0.19724354 | F30: 0.21785008 | G30: 0.26670006 | H30: 0.21356258 | I30: 0.26270427 | J30: 0.20173606 | K30: 0.25164539 | L30: 0.2204281 | M30: 0.26900711
A31: Probability of Loss
A32: Over 1 Month | B32: 0.342 | C32: 0.3834 | D32: 0.29355 | E32: 0.3447 | F32: 0.31475 | G32: 0.3525 | H32: 0.31325 | I32: 0.35175 | J32: 0.30945 | K32: 0.3482 | L32: 0.325 | M32: 0.36865
A33: Over 1 Year | B33: 0.18665 | C33: 0.2581 | D33: 0.12165 | E33: 0.19815 | F33: 0.15455 | G33: 0.22085 | H33: 0.15185 | I33: 0.21925 | J33: 0.1448 | K33: 0.2145 | L33: 0.171 | M33: 0.24375
A34: Over 3 Years | B34: 0.1081 | C34: 0.1914 | D34: 0.0569 | E34: 0.1316 | F34: 0.08025 | G34: 0.14795 | H34: 0.0786 | I34: 0.1462 | J34: 0.07445 | K34: 0.14165 | L34: 0.0999 | M34: 0.1883
A35: Portfolio Risk Premia
R54: 0 | S54: 0 | T54: 0 | U54: 0 | V54: 0 | W54: 0
Q55: Equity | R55: 0.022502648 | S55: 0.022410337 | T55: 0.022097842 | U55: 0.01644879 | V55: 0.021238865 | W55: 0.021250038
Q56: Term | R56: 0.0030363086 | S56: 0.0070147647 | T56: 0.0070690424 | U56: 0.006114489 | V56: 0.007220675 | W56: 0.013009867
Q57: Leverage | R57: 0.00013912181 | S57: 0.0036462354 | T57: 0.0036118743 | U57: 0.0022683788 | V57: 0.0035195766 | W57: 0.0033377297
Q58: Liquidity | R58: 0.00042682384 | S58: 0.004514465 | T58: 0.0044822385 | U58: 0.0027015725 | V58: 0.0043965558 | W58: 0.005832317
...

Sheet Sheet2
F3: Compensated For
E5: Equity | F5: Consumption Risk
E7: Term | F7: Inflation and Interest Rate Risk
E9: Leverage | F9: Short-Term Funding Risk
E11: Liquidity | F11: Market-wide Liquidity Risk
E13: Carry | F13: Risk Embedded in Carry Trades
E15: Emerging Markets | F15: Risk Specific to Emerging Markets

Sheet Sheet1
B4: Equity | D4: Market Risk: Earnings Growth/Discount Rate
B5: Term | D5: Inflation and Interest Rate Risk
B6: Leverage | D6: Risk in Short-Term Funding Conditions
B7: Liquidity | D7: Risk in Market-wide Liquidity Conditions
B8: Carry | D8: Risk Embedded in Carry Trades
B9: EM | D9: Risk Specific to Emerging Markets

Sheet assumptions
B1: Long-Term Estimates | I1: Modelling Dates
B2: Risk Premia with Estimated Range | E2: Volatility | F2: Sharpe Ratio | G2: Estimated Mean Return (2.5% Risk Free Rate) | H2: Hedging Ratio | I2: From | J2: To
A3: Investment Grade Fixed Income
A4: US Dollar Debt | B4: 0.0057327167 | C4: 0.010867352 | D4: 0.016001987 | E4: 0.03211081 | F4: 0.33843281 | G4: 0.035867352 | H4: 0 | I4: 26723 | J4: 45777
A5: US Short Duration Debt | B5: 0.00043830452 | C5: 0.0030901253 | D5: 0.0057419461 | E5: 0.014730739 | F5: 0.20977395 | G5: 0.028090125 | H5: 0 | I5: 33662 | J5: 45777
A6: US Inflation Protected Bonds | B6: 0.010015972 | C6: 0.019683612 | D6: 0.029351253 | E6: 0.046212231 | F6: 0.42593945 | G6: 0.044683612 | H6: 0 | I6: 36585 | J6: 45777
A7: US Corporate Bonds | B7: 0.0064340697 | C7: 0.019942198 | D7: 0.033450326 | E7: 0.042238343 | F7: 0.47213496 | G7: 0.044942198 | H7: 0 | I7: 26723 | J7: 45777
A8: Other Fixed Income
A9: US High Yield | B9: 0.013275144 | C9: 0.0329573 | D9: 0.052639455 | E9: 0.082058406 | F9: 0.40163222 | G9: 0.0579573 | H9: 0 | I9: 30559 | J9: 45777
A10: EM External Debt | B10: 0.01308276 | C10: 0.047110684 | D10: 0.081138608 | E10: 0.12201962 | F10: 0.38609106 | G10: 0.072110684 | H10: 0 | I10: 34365 | J10: 45107
A11: Public Equity
A12: Global Equities (ACWI) | B12: 0.021935922 | C12: 0.046797853 | D12: 0.071659785 | E12: 0.1469643 | F12: 0.31843007 | G12: 0.071797853 | H12: 0.7 | I12: 32171 | J12: 45777
A13: US Large Cap Growth Equity | B13: 0.01717616 | C13: 0.044244823 | D13: 0.071313487 | E13: 0.16928111 | F13: 0.26136894 | G13: 0.069244823 | H13: 0 | I13: 28886 | J13: 45777
A14: US Large Cap Value Equity | B14: 0.038328393 | C14: 0.061473145 | D14: 0.084617896 | E14: 0.14474188 | F14: 0.42470877 | G14: 0.086473145 | H14: 0 | I14: 28886 | J14: 45777
A15: US Small Cap Equity | B15: 0.039548089 | C15: 0.070287621 | D15: 0.10102715 | E15: 0.19223787 | F15: 0.36562838 | G15: 0.095287621 | H15: 0 | I15: 28886 | J15: 45777
A16: Europe ex-UK Equity | B16: 0.021019364 | C16: 0.047103365 | D16: 0.073187365 | E16: 0.16312326 | F16: 0.28875934 | G16: 0.072103365 | H16: 0.7 | I16: 25626 | J16: 45777
A17: UK Equity | B17: 0.025370931 | C17: 0.04908897 | D17: 0.07280701 | E17: 0.14832709 | F17: 0.33095081 | G17: 0.07408897 | H17: 0.7 | I17: 25598 | J17: 45777
A18: Japanese Equity | B18: -0.0015284258 | C18: 0.027945938 | D18: 0.057420302 | E18: 0.1843258 | F18: 0.15161165 | G18: 0.052945938 | H18: 0.7 | I18: 25598 | J18: 45777
A19: Asia-Pacific Equity | B19: 0.027529177 | C19: 0.056461832 | D19: 0.085394486 | E19: 0.17102723 | F19: 0.33013357 | G19: 0.081461832 | H19: 0.7 | I19: 25626 | J19: 45777
A20: Emerging Market Equity | B20: 0.035868022 | C20: 0.075245769 | D20: 0.11462352 | E20: 0.23277046 | F20: 0.32326168 | G20: 0.10024577 | H20: 0 | I20: 32171 | J20: 45777
A21: Global REITs | B21: -0.012018143 | C21: 0.05834231 | D21: 0.12870276 | E21: 0.13562199 | F21: 0.43018326 | G21: 0.08334231 | H21: 0.7 | I21: 32720 | J21: 44925
A22: Infrastructure Equity | B22: 0.016888386 | C22: 0.04562559 | D22: 0.074362794 | E22: 0.14058985 | F22: 0.32452976 | G22: 0.07062559 | H22: 0.7 | I22: 36189 | J22: 45777
A23: Hedge Funds
A24: Multi-Strategy | B24: 0.0053661961 | C24: 0.015035469 | D24: 0.024704741 | E24: 0.055490336 | F24: 0.27095652 | G24: 0.040035469 | H24: 1 | I24: 32904 | J24: 45777
A25: Event Driven | B25: 0.0078845227 | C25: 0.019381268 | D25: 0.030878014 | E25: 0.061838707 | F25: 0.31341646 | G25: 0.044381268 | H25: 1 | I25: 34365 | J25: 45777
A26: Equity Long/Short | B26: 0.0043523801 | C26: 0.020773446 | D26: 0.037194513 | E26: 0.088325647 | F26: 0.23519155 | G26: 0.045773446 | H26: 1 | I26: 34365 | J26: 45777
A27: Tactical Trading | B27: 0.0106929 | C27: 0.027968658 | D27: 0.045244417 | E27: 0.073138511 | F27: 0.38240673 | G27: 0.052968658 | H27: 1 | I27: 38383 | J27: 45777
A28: Private Equity
A29: Buyout | B29: 0.018093277 | C29: 0.065301868 | D29: 0.11251046 | E29: 0.13777198 | F29: 0.4739851 | G29: 0.090301868 | H29: 0 | I29: 25598 | J29: 45777
A30: Growth | B30: 0.013496497 | C30: 0.067090636 | D30: 0.12068477 | E30: 0.15640736 | F30: 0.42894808 | G30: 0.092090636 | H30: 0 | I30: 28886 | J30: 45777
A31: Venture | B31: 0.0048618709 | C31: 0.062172068 | D31: 0.11948227 | E31: 0.16725218 | F31: 0.3717265 | G31: 0.087172068 | H31: 0 | I31: 30680 | J31: 44925
A32: Other Private Assets
A33: Private Credit | B33: 0.020469028 | C33: 0.059395007 | D33: 0.098320985 | E33: 0.11360029 | F33: 0.52284206 | G33: 0.084395007 | H33: 0 | I33: 30589 | J33: 45777
A34: Core Real Estate | B34: 0.028995005 | C34: 0.078592058 | D34: 0.12818911 | E34: 0.14474239 | F34: 0.54297884 | G34: 0.10359206 | H34: 0 | I34: 32720 | J34: 44925
A35: Infrastructure | B35: 0.010324018 | C35: 0.060402182 | D35: 0.11048035 | E35: 0.14614645 | F35: 0.41329899 | G35: 0.085402182 | H35: 0 | I35: 36189 | J35: 45777
A36: Cash, Money Markets and Deposits
A37: Leverage (SOFR + 1%) | B37: 0.0125 | C37: 0.0125 | D37: 0.0125 | E37: 0 | G37: 0.0375 | H37: 0 | I37: 9708 | J37: 45807

Sheet ws_Current_Portfolio
B1: nominal | C1: nominal | D1: nominal | E1: nominal | F1: real | G1: real | H1: real | I1: real | J1: net_flows | K1: net_flows | L1: net_flows | M1: net_flows | N1: real_net_flows | O1: real_net_flows | P1: real_net_flows | Q1: real_net_flows
B2: 1st %ile | C2: 10th %ile | D2: 50th %ile | E2: 90th %ile | F2: 1st %ile | G2: 10th %ile | H2: 50th %ile | I2: 90th %ile | J2: 1st %ile | K2: 10th %ile | L2: 50th %ile | M2: 90th %ile | N2: 1st %ile | O2: 10th %ile | P2: 50th %ile | Q2: 90th %ile
A3: 0 | B3: 100 | C3: 100 | D3: 100 | E3: 100 | F3: 100 | G3: 100 | H3: 100 | I3: 100 | J3: 0 | K3: 0 | L3: 0 | M3: 0 | N3: 0 | O3: 0 | P3: 0 | Q3: 0
A4: 1 | B4: 89.456903 | C4: 97.025266 | D4: 106.39677 | E4: 115.14688 | F4: 86.703805 | G4: 94.656689 | H4: 104.04281 | I4: 112.75779 | J4: 0 | K4: 0 | L4: 0 | M4: 0 | N4: 0 | O4: 0 | P4: 0 | Q4: 0
A5: 2 | B5: 89.980738 | C5: 99.192369 | D5: 111.90511 | E5: 125.37894 | F5: 85.100895 | G5: 94.40029 | H5: 106.92815 | I5: 120.0688 | J5: 0 | K5: 0 | L5: 0 | M5: 0 | N5: 0 | O5: 0 | P5: 0 | Q5: 0
A6: 3 | B6: 90.889866 | C6: 102.40888 | D6: 117.86125 | E6: 134.91703 | F6: 84.218811 | G6: 95.332301 | H6: 110.17253 | I6: 126.45714 | J6: 0 | K6: 0 | L6: 0 | M6: 0 | N6: 0 | O6: 0 | P6: 0 | Q6: 0
A7: 4 | B7: 90.427869 | C7: 105.39812 | D7: 124.98892 | E7: 147.08282 | F7: 82.138292 | G7: 96.009494 | H7: 114.35235 | I7: 134.98152 | J7: 0 | K7: 0 | L7: 0 | M7: 0 | N7: 0 | O7: 0 | P7: 0 | Q7: 0
A8: 5 | B8: 91.369198 | C8: 109.18664 | D8: 132.89853 | E8: 159.97582 | F8: 81.549878 | G8: 97.326335 | H8: 118.94104 | I8: 143.81495 | J8: 0 | K8: 0 | L8: 0 | M8: 0 | N8: 0 | O8: 0 | P8: 0 | Q8: 0
A9: 6 | B9: 92.173075 | C9: 113.09198 | D9: 140.76888 | E9: 172.92344 | F9: 80.402802 | G9: 98.598671 | H9: 123.44725 | I9: 152.12769 | J9: 0 | K9: 0 | L9: 0 | M9: 0 | N9: 0 | O9: 0 | P9: 0 | Q9: 0
A10: 7 | B10: 91.064146 | C10: 116.06268 | D10: 149.36103 | E10: 187.42409 | F10: 78.257879 | G10: 99.337506 | H10: 128.22462 | I10: 161.49801 | J10: 0 | K10: 0 | L10: 0 | M10: 0 | N10: 0 | O10: 0 | P10: 0 | Q10: 0
A11: 8 | B11: 92.49818 | C11: 119.33159 | D11: 158.21366 | E11: 202.89697 | F11: 77.685826 | G11: 100.23988 | H11: 133.08611 | I11: 171.48036 | J11: 0 | K11: 0 | L11: 0 | M11: 0 | N11: 0 | O11: 0 | P11: 0 | Q11: 0
A12: 9 | B12: 91.512381 | C12: 122.42954 | D12: 166.84262 | E12: 219.07229 | F12: 76.198095 | G12: 100.92254 | H12: 137.65239 | I12: 181.19235 | J12: 0 | K12: 0 | L12: 0 | M12: 0 | N12: 0 | O12: 0 | P12: 0 | Q12: 0
A13: 10 | B13: 92.934748 | C13: 126.25256 | D13: 175.82877 | E13: 235.56849 | F13: 75.42308 | G13: 101.92611 | H13: 141.93034 | I13: 191.00777 | J13: 0 | K13: 0 | L13: 0 | M13: 0 | N13: 0 | O13: 0 | P13: 0 | Q13: 0
A14: 11 | B14: 93.814016 | C14: 129.33699 | D14: 185.18393 | E14: 253.54932 | F14: 75.67813 | G14: 102.69387 | H14: 146.89473 | I14: 201.21542 | J14: 0 | K14: 0 | L14: 0 | M14: 0 | N14: 0 | O14: 0 | P14: 0 | Q14: 0
... A23: 20 | B23: 110.67118 | C23: 173.23978 | D23: 290.67048 | E23: 475.19458 | F23: 75.081859 | G23: 115.66842 | H23: 193.38003 | I23: 313.21326 | J23: 0 | K23: 0 | L23: 0 | M23: 0 | N23: 0 | O23: 0 | P23: 0 | Q23: 0

Sheet ws_Volatility_Matched
B1: nominal | C1: nominal | D1: nominal | E1: nominal | F1: real | G1: real | H1: real | I1: real | J1: net_flows | K1: net_flows | L1: net_flows | M1: net_flows | N1: real_net_flows | O1: real_net_flows | P1: real_net_flows | Q1: real_net_flows
B2: 1st %ile | C2: 10th %ile | D2: 50th %ile | E2: 90th %ile | F2: 1st %ile | G2: 10th %ile | H2: 50th %ile | I2: 90th %ile | J2: 1st %ile | K2: 10th %ile | L2: 50th %ile | M2: 90th %ile | N2: 1st %ile | O2: 10th %ile | P2: 50th %ile | Q2: 90th %ile
A3: 0 | B3: 100 | C3: 100 | D3: 100 | E3: 100 | F3: 100 | G3: 100 | H3: 100 | I3: 100 | J3: 0 | K3: 0 | L3: 0 | M3: 0 | N3: 0 | O3: 0 | P3: 0 | Q3: 0
A4: 1 | B4: 89.421235 | C4: 98.89747 | D4: 108.53337 | E4: 117.87519 | F4: 86.443445 | G4: 96.423857 | H4: 106.15549 | I4: 115.6391 | J4: 0 | K4: 0 | L4: 0 | M4: 0 | N4: 0 | O4: 0 | P4: 0 | Q4: 0
A5: 2 | B5: 92.010362 | C5: 102.6739 | D5: 116.83514 | E5: 130.47928 | F5: 86.756945 | G5: 97.539956 | H5: 111.66255 | I5: 125.21087 | J5: 0 | K5: 0 | L5: 0 | M5: 0 | N5: 0 | O5: 0 | P5: 0 | Q5: 0
A6: 3 | B6: 94.684758 | C6: 108.28897 | D6: 125.31051 | E6: 143.35926 | F6: 87.43358 | G6: 100.59831 | H6: 117.1762 | I6: 134.62796 | J6: 0 | K6: 0 | L6: 0 | M6: 0 | N6: 0 | O6: 0 | P6: 0 | Q6: 0
A7: 4 | B7: 96.26044 | C7: 113.03378 | D7: 134.91119 | E7: 158.56791 | F7: 87.076215 | G7: 102.59279 | H7: 123.56686 | I7: 145.95834 | J7: 0 | K7: 0 | L7: 0 | M7: 0 | N7: 0 | O7: 0 | P7: 0 | Q7: 0
A8: 5 | B8: 99.421422 | C8: 119.01088 | D8: 145.63378 | E8: 175.09807 | F8: 87.812029 | G8: 105.77129 | H8: 130.35953 | I8: 157.81637 | J8: 0 | K8: 0 | L8: 0 | M8: 0 | N8: 0 | O8: 0 | P8: 0 | Q8: 0
A9: 6 | B9: 102.29618 | C9: 125.42515 | D9: 156.54597 | E9: 191.92979 | F9: 88.934728 | G9: 108.93202 | H9: 137.25276 | I9: 169.42508 | J9: 0 | K9: 0 | L9: 0 | M9: 0 | N9: 0 | O9: 0 | P9: 0 | Q9: 0
A10: 7 | B10: 102.59313 | C10: 130.38813 | D10: 167.66805 | E10: 210.45257 | F10: 87.431451 | G10: 111.16227 | H10: 143.94682 | I10: 181.91959 | J10: 0 | K10: 0 | L10: 0 | M10: 0 | N10: 0 | O10: 0 | P10: 0 | Q10: 0
A11: 8 | B11: 104.73214 | C11: 135.64702 | D11: 179.41634 | E11: 230.09452 | F11: 87.590743 | G11: 113.46212 | H11: 151.01566 | I11: 194.92893 | J11: 0 | K11: 0 | L11: 0 | M11: 0 | N11: 0 | O11: 0 | P11: 0 | Q11: 0
A12: 9 | B12: 105.28952 | C12: 140.65451 | D12: 191.02226 | E12: 251.04664 | F12: 87.321894 | G12: 115.37314 | H12: 157.52577 | I12: 209.14064 | J12: 0 | K12: 0 | L12: 0 | M12: 0 | N12: 0 | O12: 0 | P12: 0 | Q12: 0
A13: 10 | B13: 108.38574 | C13: 146.86495 | D13: 203.57367 | E13: 273.18313 | F13: 87.174699 | G13: 118.30073 | H13: 164.29285 | I13: 222.83676 | J13: 0 | K13: 0 | L13: 0 | M13: 0 | N13: 0 | O13: 0 | P13: 0 | Q13: 0
A14: 11 | B14: 110.8092 | C14: 153.15847 | D14: 216.57347 | E14: 296.36069 | F14: 87.664921 | G14: 120.85498 | H14: 171.46897 | I14: 236.75433 | J14: 0 | K14: 0 | L14: 0 | M14: 0 | N14: 0 | O14: 0 | P14: 0 | Q14: 0
... A23: 20 | B23: 146.73475 | C23: 225.96671 | D23: 375.23052 | E23: 605.27008 | F23: 98.81061 | G23: 149.88169 | H23: 249.85944 | I23: 401.5356 | J23: 0 | K23: 0 | L23: 0 | M23: 0 | N23: 0 | O23: 0 | P23: 0 | Q23: 0

Sheet ws_CVaR_Matched
B1: nominal | C1: nominal | D1: nominal | E1: nominal | F1: real | G1: real | H1: real | I1: real | J1: net_flows | K1: net_flows | L1: net_flows | M1: net_flows | N1: real_net_flows | O1: real_net_flows | P1: real_net_flows | Q1: real_net_flows
B2: 1st %ile | C2: 10th %ile | D2: 50th %ile | E2: 90th %ile | F2: 1st %ile | G2: 10th %ile | H2: 50th %ile | I2: 90th %ile | J2: 1st %ile | K2: 10th %ile | L2: 50th %ile | M2: 90th %ile | N2: 1st %ile | O2: 10th %ile | P2: 50th %ile | Q2: 90th %ile
A3: 0 | B3: 100 | C3: 100 | D3: 100 | E3: 100 | F3: 100 | G3: 100 | H3: 100 | I3: 100 | J3: 0 | K3: 0 | L3: 0 | M3: 0 | N3: 0 | O3: 0 | P3: 0 | Q3: 0
A4: 1 | B4: 89.641213 | C4: 99.002993 | D4: 108.52341 | E4: 117.73462 | F4: 86.612477 | G4: 96.545101 | H4: 106.14499 | I4: 115.51202 | J4: 0 | K4: 0 | L4: 0 | M4: 0 | N4: 0 | O4: 0 | P4: 0 | Q4: 0
A5: 2 | B5: 92.223138 | C5: 102.82984 | D5: 116.81852 | E5: 130.27699 | F5: 86.951416 | G5: 97.669721 | H5: 111.6486 | I5: 125.00108 | J5: 0 | K5: 0 | L5: 0 | M5: 0 | N5: 0 | O5: 0 | P5: 0 | Q5: 0
A6: 3 | B6: 94.972248 | C6: 108.49168 | D6: 125.29771 | E6: 143.0708 | F6: 87.687518 | G6: 100.73337 | H6: 117.15955 | I6: 134.34018 | J6: 0 | K6: 0 | L6: 0 | M6: 0 | N6: 0 | O6: 0 | P6: 0 | Q6: 0
A7: 4 | B7: 96.674065 | C7: 113.25979 | D7: 134.85301 | E7: 158.17594 | F7: 87.424395 | G7: 102.80976 | H7: 123.51423 | I7: 145.60598 | J7: 0 | K7: 0 | L7: 0 | M7: 0 | N7: 0 | O7: 0 | P7: 0 | Q7: 0
A8: 5 | B8: 99.78831 | C8: 119.25648 | D8: 145.59298 | E8: 174.61668 | F8: 88.053708 | G8: 105.96196 | H8: 130.32029 | I8: 157.36456 | J8: 0 | K8: 0 | L8: 0 | M8: 0 | N8: 0 | O8: 0 | P8: 0 | Q8: 0
A9: 6 | B9: 102.82181 | C9: 125.68126 | D9: 156.46125 | E9: 191.31412 | F9: 89.256112 | G9: 109.18011 | H9: 137.14888 | I9: 168.81993 | J9: 0 | K9: 0 | L9: 0 | M9: 0 | N9: 0 | O9: 0 | P9: 0 | Q9: 0
A10: 7 | B10: 103.15007 | C10: 130.66308 | D10: 167.51212 | E10: 209.57338 | F10: 87.994316 | G10: 111.39822 | H10: 143.83698 | I10: 181.26733 | J10: 0 | K10: 0 | L10: 0 | M10: 0 | N10: 0 | O10: 0 | P10: 0 | Q10: 0
A11: 8 | B11: 105.21777 | C11: 135.97833 | D11: 179.22694 | E11: 229.04359 | F11: 88.25309 | G11: 113.70714 | H11: 150.83641 | I11: 194.02594 | J11: 0 | K11: 0 | L11: 0 | M11: 0 | N11: 0 | O11: 0 | P11: 0 | Q11: 0
A12: 9 | B12: 105.89768 | C12: 140.95494 | D12: 190.69848 | E12: 249.93548 | F12: 87.726288 | G12: 115.69798 | H12: 157.25916 | I12: 208.21924 | J12: 0 | K12: 0 | L12: 0 | M12: 0 | N12: 0 | O12: 0 | P12: 0 | Q12: 0
A13: 10 | B13: 109.14763 | C13: 147.2255 | D13: 203.2166 | E13: 271.76727 | F13: 87.62914 | G13: 118.50161 | H13: 164.00649 | I13: 221.65202 | J13: 0 | K13: 0 | L13: 0 | M13: 0 | N13: 0 | O13: 0 | P13: 0 | Q13: 0
A14: 11 | B14: 111.38112 | C14: 153.55135 | D14: 216.14308 | E14: 294.6206 | F14: 88.346651 | G14: 121.097 | H14: 171.11655 | I14: 235.37806 | J14: 0 | K14: 0 | L14: 0 | M14: 0 | N14: 0 | O14: 0 | P14: 0 | Q14: 0
... A23: 20 | B23: 147.87052 | C23: 226.3154 | D23: 373.60695 | E23: 599.92465 | F23: 99.4494 | G23: 150.03954 | H23: 248.80286 | I23: 397.63462 | J23: 0 | K23: 0 | L23: 0 | M23: 0 | N23: 0 | O23: 0 | P23: 0 | Q23: 0

Sheet ws_Return_Matched
B1: nominal | C1: nominal | D1: nominal | E1: nominal | F1: real | G1: real | H1: real | I1: real | J1: net_flows | K1: net_flows | L1: net_flows | M1: net_flows | N1: real_net_flows | O1: real_net_flows | P1: real_net_flows | Q1: real_net_flows
B2: 1st %ile | C2: 10th %ile | D2: 50th %ile | E2: 90th %ile | F2: 1st %ile | G2: 10th %ile | H2: 50th %ile | I2: 90th %ile | J2: 1st %ile | K2: 10th %ile | L2: 50th %ile | M2: 90th %ile | N2: 1st %ile | O2: 10th %ile | P2: 50th %ile | Q2: 90th %ile
A3: 0 | B3: 100 | C3: 100 | D3: 100 | E3: 100 | F3: 100 | G3: 100 | H3: 100 | I3: 100 | J3: 0 | K3: 0 | L3: 0 | M3: 0 | N3: 0 | O3: 0 | P3: 0 | Q3: 0
A4: 1 | B4: 93.093661 | C4: 100.30005 | D4: 107.52814 | E4: 114.34957 | F4: 89.964 | G4: 97.802672 | H4: 105.18058 | I4: 112.15871 | J4: 0 | K4: 0 | L4: 0 | M4: 0 | N4: 0 | O4: 0 | P4: 0 | Q4: 0
A5: 2 | B5: 96.286939 | C5: 104.3702 | D5: 114.74861 | E5: 124.67458 | F5: 90.645758 | G5: 99.09348 | H5: 109.66217 | I5: 119.60253 | J5: 0 | K5: 0 | L5: 0 | M5: 0 | N5: 0 | O5: 0 | P5: 0 | Q5: 0
A6: 3 | B6: 99.3796 | C6: 109.68157 | D6: 122.14639 | E6: 135.04355 | F6: 91.582844 | G6: 101.8533 | H6: 114.18233 | I6: 126.83568 | J6: 0 | K6: 0 | L6: 0 | M6: 0 | N6: 0 | O6: 0 | P6: 0 | Q6: 0
A7: 4 | B7: 101.5626 | C7: 114.39721 | D7: 130.34407 | E7: 147.13222 | F7: 91.657605 | G7: 103.84871 | H7: 119.36644 | I7: 135.43296 | J7: 0 | K7: 0 | L7: 0 | M7: 0 | N7: 0 | O7: 0 | P7: 0 | Q7: 0
A8: 5 | B8: 105.0082 | C8: 120.06085 | D8: 139.38826 | E8: 160.18072 | F8: 92.977125 | G8: 106.72912 | H8: 124.81817 | I8: 144.37706 | J8: 0 | K8: 0 | L8: 0 | M8: 0 | N8: 0 | O8: 0 | P8: 0 | Q8: 0
A9: 6 | B9: 107.95213 | C9: 125.86019 | D9: 148.70461 | E9: 173.34646 | F9: 93.572726 | G9: 109.33156 | H9: 130.40261 | I9: 153.09519 | J9: 0 | K9: 0 | L9: 0 | M9: 0 | N9: 0 | O9: 0 | P9: 0 | Q9: 0
A10: 7 | B10: 108.67147 | C10: 130.52026 | D10: 157.71513 | E10: 187.31087 | F10: 92.743011 | G10: 111.26011 | H10: 135.57384 | I10: 162.18489 | J10: 0 | K10: 0 | L10: 0 | M10: 0 | N10: 0 | O10: 0 | P10: 0 | Q10: 0
A11: 8 | B11: 110.84379 | C11: 135.07761 | D11: 167.02655 | E11: 202.07017 | F11: 92.897848 | G11: 112.92086 | H11: 140.70925 | I11: 171.27298 | J11: 0 | K11: 0 | L11: 0 | M11: 0 | N11: 0 | O11: 0 | P11: 0 | Q11: 0
A12: 9 | B12: 112.06429 | C12: 139.24085 | D12: 176.31509 | E12: 217.39048 | F12: 92.706718 | G12: 114.29811 | H12: 145.62726 | I12: 180.86071 | J12: 0 | K12: 0 | L12: 0 | M12: 0 | N12: 0 | O12: 0 | P12: 0 | Q12: 0
A13: 10 | B13: 114.6986 | C13: 144.57473 | D13: 185.97743 | E13: 233.53062 | F13: 92.300514 | G13: 116.18205 | H13: 150.42529 | I13: 190.37182 | J13: 0 | K13: 0 | L13: 0 | M13: 0 | N13: 0 | O13: 0 | P13: 0 | Q13: 0
A14: 11 | B14: 117.23027 | C14: 149.6873 | D14: 196.0513 | E14: 250.77972 | F14: 92.336628 | G14: 118.06843 | H14: 155.16586 | I14: 199.94227 | J14: 0 | K14: 0 | L14: 0 | M14: 0 | N14: 0 | O14: 0 | P14: 0 | Q14: 0
... A23: 20 | B23: 149.56088 | C23: 209.04027 | D23: 311.64269 | E23: 463.68758 | F23: 99.692153 | G23: 139.113 | H23: 207.38083 | I23: 305.47999 | J23: 0 | K23: 0 | L23: 0 | M23: 0 | N23: 0 | O23: 0 | P23: 0 | Q23: 0

Sheet ws_Max_Drawdown_Matched
B1: nominal | C1: nominal | D1: nominal | E1: nominal | F1: real | G1: real | H1: real | I1: real | J1: net_flows | K1: net_flows | L1: net_flows | M1: net_flows | N1: real_net_flows | O1: real_net_flows | P1: real_net_flows | Q1: real_net_flows
B2: 1st %ile | C2: 10th %ile | D2: 50th %ile | E2: 90th %ile | F2: 1st %ile | G2: 10th %ile | H2: 50th %ile | I2: 90th %ile | J2: 1st %ile | K2: 10th %ile | L2: 50th %ile | M2: 90th %ile | N2: 1st %ile | O2: 10th %ile | P2: 50th %ile | Q2: 90th %ile
A3: 0 | B3: 100 | C3: 100 | D3: 100 | E3: 100 | F3: 100 | G3: 100 | H3: 100 | I3: 100 | J3: 0 | K3: 0 | L3: 0 | M3: 0 | N3: 0 | O3: 0 | P3: 0 | Q3: 0
A4: 1 | B4: 90.143957 | C4: 99.296273 | D4: 108.4612 | E4: 117.41215 | F4: 87.077528 | G4: 96.816436 | H4: 106.11689 | I4: 115.16285 | J4: 0 | K4: 0 | L4: 0 | M4: 0 | N4: 0 | O4: 0 | P4: 0 | Q4: 0
A5: 2 | B5: 92.904964 | C5: 103.22217 | D5: 116.80167 | E5: 129.75208 | F5: 87.580068 | G5: 98.021361 | H5: 111.62229 | I5: 124.48919 | J5: 0 | K5: 0 | L5: 0 | M5: 0 | N5: 0 | O5: 0 | P5: 0 | Q5: 0
A6: 3 | B6: 95.867023 | C6: 109.00382 | D6: 125.25322 | E6: 142.2478 | F6: 88.479851 | G6: 101.18498 | H6: 117.12898 | I6: 133.67474 | J6: 0 | K6: 0 | L6: 0 | M6: 0 | N6: 0 | O6: 0 | P6: 0 | Q6: 0
A7: 4 | B7: 97.698127 | C7: 113.8286 | D7: 134.80108 | E7: 157.18477 | F7: 88.372382 | G7: 103.35408 | H7: 123.45065 | I7: 144.66426 | J7: 0 | K7: 0 | L7: 0 | M7: 0 | N7: 0 | O7: 0 | P7: 0 | Q7: 0
A8: 5 | B8: 100.99603 | C8: 119.97845 | D8: 145.39875 | E8: 173.22714 | F8: 89.293012 | G8: 106.50233 | H8: 130.20117 | I8: 156.23788 | J8: 0 | K8: 0 | L8: 0 | M8: 0 | N8: 0 | O8: 0 | P8: 0 | Q8: 0
A9: 6 | B9: 104.1096 | C9: 126.40303 | D9: 156.22811 | E9: 189.62018 | F9: 90.333539 | G9: 109.78062 | H9: 136.95911 | I9: 167.43288 | J9: 0 | K9: 0 | L9: 0 | M9: 0 | N9: 0 | O9: 0 | P9: 0 | Q9: 0
A10: 7 | B10: 104.78905 | C10: 131.41465 | D10: 167.08036 | E10: 207.56665 | F10: 89.34603 | G10: 112.03024 | H10: 143.5902 | I10: 179.43149 | J10: 0 | K10: 0 | L10: 0 | M10: 0 | N10: 0 | O10: 0 | P10: 0 | Q10: 0
A11: 8 | B11: 106.88693 | C11: 136.81306 | D11: 178.54993 | E11: 226.35858 | F11: 89.667658 | G11: 114.37896 | H11: 150.37684 | I11: 191.78579 | J11: 0 | K11: 0 | L11: 0 | M11: 0 | N11: 0 | O11: 0 | P11: 0 | Q11: 0
A12: 9 | B12: 107.59776 | C12: 141.84624 | D12: 189.94717 | E12: 246.42008 | F12: 89.151397 | G12: 116.3316 | H12: 156.66048 | I12: 205.32527 | J12: 0 | K12: 0 | L12: 0 | M12: 0 | N12: 0 | O12: 0 | P12: 0 | Q12: 0
A13: 10 | B13: 110.9318 | C13: 148.14571 | D13: 202.19948 | E13: 267.89127 | F13: 89.088322 | G13: 119.20274 | H13: 163.28072 | I13: 218.53068 | J13: 0 | K13: 0 | L13: 0 | M13: 0 | N13: 0 | O13: 0 | P13: 0 | Q13: 0
A14: 11 | B14: 113.1209 | C14: 154.60565 | D14: 214.83607 | E14: 290.39334 | F14: 89.773348 | G14: 121.67785 | H14: 170.11897 | I14: 231.72916 | J14: 0 | K14: 0 | L14: 0 | M14: 0 | N14: 0 | O14: 0 | P14: 0 | Q14: 0
... A23: 20 | B23: 150.74441 | C23: 227.23738 | D23: 368.87926 | E23: 584.88415 | F23: 100.81517 | G23: 150.54649 | H23: 245.65763 | I23: 387.61514 | J23: 0 | K23: 0 | L23: 0 | M23: 0 | N23: 0 | O23: 0 | P23: 0 | Q23: 0

Sheet ws_Volatility_Parity
B1: nominal | C1: nominal | D1: nominal | E1: nominal | F1: real | G1: real | H1: real | I1: real | J1: net_flows | K1: net_flows | L1: net_flows | M1: net_flows | N1: real_net_flows | O1: real_net_flows | P1: real_net_flows | Q1: real_net_flows
B2: 1st %ile | C2: 10th %ile | D2: 50th %ile | E2: 90th %ile | F2: 1st %ile | G2: 10th %ile | H2: 50th %ile | I2: 90th %ile | J2: 1st %ile | K2: 10th %ile | L2: 50th %ile | M2: 90th %ile | N2: 1st %ile | O2: 10th %ile | P2: 50th %ile | Q2: 90th %ile
A3: 0 | B3: 100 | C3: 100 | D3: 100 | E3: 100 | F3: 100 | G3: 100 | H3: 100 | I3: 100 | J3: 0 | K3: 0 | L3: 0 | M3: 0 | N3: 0 | O3: 0 | P3: 0 | Q3: 0
A4: 1 | B4: 87.740045 | C4: 98.270763 | D4: 108.67508 | E4: 118.67695 | F4: 84.701099 | G4: 95.813942 | H4: 106.30645 | I4: 116.39103 | J4: 0 | K4: 0 | L4: 0 | M4: 0 | N4: 0 | O4: 0 | P4: 0 | Q4: 0
A5: 2 | B5: 90.189716 | C5: 101.5001 | D5: 117.60279 | E5: 131.89229 | F5: 84.897035 | G5: 96.299128 | H5: 112.34588 | I5: 126.62973 | J5: 0 | K5: 0 | L5: 0 | M5: 0 | N5: 0 | O5: 0 | P5: 0 | Q5: 0
A6: 3 | B6: 92.689227 | C6: 107.35984 | D6: 126.30765 | E6: 145.04094 | F6: 85.207159 | G6: 99.579784 | H6: 118.14766 | I6: 136.37357 | J6: 0 | K6: 0 | L6: 0 | M6: 0 | N6: 0 | O6: 0 | P6: 0 | Q6: 0
A7: 4 | B7: 94.077191 | C7: 111.7962 | D7: 135.41053 | E7: 160.23349 | F7: 84.735584 | G7: 101.39768 | H7: 124.02504 | I7: 147.60946 | J7: 0 | K7: 0 | L7: 0 | M7: 0 | N7: 0 | O7: 0 | P7: 0 | Q7: 0
A8: 5 | B8: 97.111906 | C8: 117.42021 | D8: 145.2338 | E8: 176.21299 | F8: 85.59778 | G8: 104.10595 | H8: 130.21404 | I8: 159.06788 | J8: 0 | K8: 0 | L8: 0 | M8: 0 | N8: 0 | O8: 0 | P8: 0 | Q8: 0
A9: 6 | B9: 100.03103 | C9: 123.3165 | D9: 155.67772 | E9: 192.16303 | F9: 86.43119 | G9: 106.78808 | H9: 136.56955 | I9: 170.16187 | J9: 0 | K9: 0 | L9: 0 | M9: 0 | N9: 0 | O9: 0 | P9: 0 | Q9: 0
A10: 7 | B10: 101.11843 | C10: 127.27231 | D10: 165.1667 | E10: 208.91152 | F10: 85.23529 | G10: 108.13283 | H10: 142.07152 | I10: 181.34623 | J10: 0 | K10: 0 | L10: 0 | M10: 0 | N10: 0 | O10: 0 | P10: 0 | Q10: 0
A11: 8 | B11: 101.89092 | C11: 131.75203 | D11: 174.76394 | E11: 225.97979 | F11: 84.483316 | G11: 109.83944 | H11: 147.44498 | I11: 192.08807 | J11: 0 | K11: 0 | L11: 0 | M11: 0 | N11: 0 | O11: 0 | P11: 0 | Q11: 0
A12: 9 | B12: 103.24124 | C12: 135.6651 | D12: 184.69585 | E12: 243.90545 | F12: 84.128072 | G12: 110.73071 | H12: 152.63286 | I12: 203.63227 | J12: 0 | K12: 0 | L12: 0 | M12: 0 | N12: 0 | O12: 0 | P12: 0 | Q12: 0
A13: 10 | B13: 104.72878 | C13: 140.71806 | D13: 194.89982 | E13: 263.42095 | F13: 83.84278 | G13: 112.57708 | H13: 157.44968 | I13: 215.19403 | J13: 0 | K13: 0 | L13: 0 | M13: 0 | N13: 0 | O13: 0 | P13: 0 | Q13: 0
A14: 11 | B14: 106.86055 | C14: 145.73582 | D14: 205.16184 | E14: 283.2589 | F14: 83.259363 | G14: 114.25878 | H14: 162.80501 | I14: 227.12856 | J14: 0 | K14: 0 | L14: 0 | M14: 0 | N14: 0 | O14: 0 | P14: 0 | Q14: 0
... A23: 20 | B23: 132.09846 | C23: 201.24289 | D23: 329.36104 | E23: 526.73934 | F23: 86.973502 | G23: 131.65715 | H23: 219.85721 | I23: 352.65533 | J23: 0 | K23: 0 | L23: 0 | M23: 0 | N23: 0 | O23: 0 | P23: 0 | Q23: 0
