Workbook

Sheet portfolios
B1: 0 | C1: 1 | D1: 2 | E1: 3 | F1: 4 | G1: 5 | H1: 6 | I1: 7 | J1: 8 | K1: 9 | L1: 10 | M1: 11 | N1: 12 | O1: 13 | P1: 14 | Q1: 15 | R1: 16 | S1: 17 | T1: 18 | U1: 19
A2: Fixed Income | B2: 0.5 | C2: 0.49392557 | D2: 0.48209952 | E2: 0.46722918 | F2: 0.4512852 | G2: 0.43628218 | H2: 0.4233451 | I2: 0.41271508 | J2: 0.40467661 | K2: 0.39958793 | L2: 0.39744748 | M2: 0.39727756 | N2: 0.39800772 | O2: 0.39887028 | P2: 0.3995999 | Q2: 0.39999807 | R2: 0.40019903 | S2: 0.40024398 | T2: 0.40023862 | U2: 0.40015678
A3: Bloomberg U.S. Treasury: Intermediate USD | B3: 50 | C3: 49.392557 | D3: 48.209952 | E3: 46.722918 | F3: 45.12852 | G3: 43.628218 | H3: 42.33451 | I3: 41.271508 | J3: 40.467661 | K3: 39.958793 | L3: 39.744748 | M3: 39.727756 | N3: 39.800772 | O3: 39.887028 | P3: 39.95999 | Q3: 39.999807 | R3: 40.019903 | S3: 40.024398 | T3: 40.023862 | U3: 40.015678
A4: Equity Index | B4: 0.5 | C4: 0.49392557 | D4: 0.48209952 | E4: 0.46722918 | F4: 0.4512852 | G4: 0.43628218 | H4: 0.4233451 | I4: 0.41271508 | J4: 0.40467661 | K4: 0.39958793 | L4: 0.39744748 | M4: 0.39727756 | N4: 0.39800772 | O4: 0.39887028 | P4: 0.3995999 | Q4: 0.39999807 | R4: 0.40019903 | S4: 0.40024398 | T4: 0.40023862 | U4: 0.40015678
A5: MSCI All Country World | B5: 50 | C5: 49.392557 | D5: 48.209952 | E5: 46.722918 | F5: 45.12852 | G5: 43.628218 | H5: 42.33451 | I5: 41.271508 | J5: 40.467661 | K5: 39.958793 | L5: 39.744748 | M5: 39.727756 | N5: 39.800772 | O5: 39.887028 | P5: 39.95999 | Q5: 39.999807 | R5: 40.019903 | S5: 40.024398 | T5: 40.023862 | U5: 40.015678
A6: Private Equity | B6: 0 | C6: 0.0071030884 | D6: 0.021048401 | E6: 0.040389114 | F6: 0.062680884 | G6: 0.08634577 | H6: 0.10993974 | I6: 0.13152757 | J6: 0.14856284 | K6: 0.15959806 | L6: 0.16459185 | M6: 0.16544247 | N6: 0.16430272 | O6: 0.16272785 | P6: 0.16131475 | Q6: 0.1604625 | R6: 0.15998948 | S6: 0.15983402 | T6: 0.15981427 | U6: 0.15995205
A7: Buyout | B7: 0 | C7: 0.43049927 | D7: 1.2763532 | E7: 2.5118273 | F7: 3.9429034 | G7: 5.4643202 | H7: 6.9787558 | I7: 8.3568329 | J7: 9.4288124 | K7: 10.09925 | L7: 10.373131 | M7: 10.3873 | N7: 10.291623 | O7: 10.184369 | P7: 10.095147 | Q7: 10.043366 | R7: 10.015862 | S7: 10.008195 | T7: 10.008658 | U7: 10.018388
A8: Growth | B8: 0 | C8: 0.20718994 | D8: 0.61384276 | E8: 1.1281021 | F8: 1.711143 | G8: 2.3203498 | H8: 2.9146263 | I8: 3.4394447 | J8: 3.8291445 | K8: 4.0554776 | L8: 4.1331279 | M8: 4.123232 | N8: 4.08178 | O8: 4.0407638 | P8: 4.0080201 | Q8: 3.9899807 | R8: 3.9810732 | S8: 3.9794269 | T8: 3.9803557 | U8: 3.9844752
A9: Venture | B9: 0 | C9: 0.072619629 | D9: 0.21464421 | E9: 0.39898209 | F9: 0.61404199 | G9: 0.84990702 | H9: 1.1005916 | I9: 1.356479 | J9: 1.5983267 | K9: 1.8050781 | L9: 1.9529263 | M9: 2.0337152 | N9: 2.0568694 | O9: 2.047652 | P9: 2.0283081 | Q9: 2.0129032 | R9: 2.0020135 | S9: 1.99578 | T9: 1.9924135 | U9: 1.9923418
A10: Other Private Assets | B10: 0 | C10: 0.0050457764 | D10: 0.014752558 | E10: 0.025152536 | F10: 0.034748725 | G10: 0.041089862 | H10: 0.043370063 | I10: 0.043042276 | J10: 0.042083943 | K10: 0.041226071 | L10: 0.0405132 | M10: 0.040002403 | N10: 0.039681848 | O10: 0.039531602 | P10: 0.039485442 | Q10: 0.03954137 | R10: 0.039612455 | S10: 0.039678022 | T10: 0.03970848 | U10: 0.039734385
A11: Private Credit | B11: 0 | C11: 0.50457764 | D11: 1.4752558 | E11: 2.5152536 | F11: 3.4748725 | G11: 4.1089862 | H11: 4.3370063 | I11: 4.3042276 | J11: 4.2083943 | K11: 4.1226071 | L11: 4.05132 | M11: 4.0002403 | N11: 3.9681848 | O11: 3.9531602 | P11: 3.9485442 | Q11: 3.954137 | R11: 3.9612455 | S11: 3.9678022 | T11: 3.970848 | U11: 3.9734385
A12: TOTAL | B12: 1 | C12: 1 | D12: 1 | E12: 1 | F12: 1 | G12: 1 | H12: 1 | I12: 1 | J12: 1 | K12: 1 | L12: 1 | M12: 1 | N12: 1 | O12: 1 | P12: 1 | Q12: 1 | R12: 1 | S12: 1 | T12: 1 | U12: 1
B13: 0 | C13: 0 | D13: 0 | E13: 0 | F13: 0 | G13: 0 | H13: 0 | I13: 0 | J13: 0 | K13: 0 | L13: 0 | M13: 0 | N13: 0 | O13: 0 | P13: 0 | Q13: 0 | R13: 0 | S13: 0 | T13: 0 | U13: 0
A14: Estimated Mean Return | B14: 0.053832603 | C14: 0.054247291 | D14: 0.055055358 | E14: 0.056081978 | F14: 0.057191923 | G14: 0.05825228 | H14: 0.059185207 | I14: 0.05996386 | J14: 0.060555237 | K14: 0.060929042 | L14: 0.061086137 | M14: 0.061098841 | N14: 0.061046012 | O14: 0.060983541 | P14: 0.060930615 | Q14: 0.060901403 | R14: 0.060886506 | S14: 0.060883006 | T14: 0.060883339 | U14: 0.060889231
A15: Sharpe Ratio | B15: 0.38304714 | C15: 0.38736617 | D15: 0.39550719 | E15: 0.40485995 | F15: 0.41392428 | G15: 0.42122596 | H15: 0.42627987 | I15: 0.42956382 | J15: 0.43166455 | K15: 0.43280773 | L15: 0.43311888 | M15: 0.43295292 | N15: 0.43262544 | O15: 0.43233539 | P15: 0.43212221 | Q15: 0.43203093 | R15: 0.43199882 | S15: 0.43200814 | T15: 0.43202111 | U15: 0.4320528
B16: 0 | C16: 0 | D16: 0 | E16: 0 | F16: 0 | G16: 0 | H16: 0 | I16: 0 | J16: 0 | K16: 0 | L16: 0 | M16: 0 | N16: 0 | O16: 0 | P16: 0 | Q16: 0 | R16: 0 | S16: 0 | T16: 0 | U16: 0
A17: Volatility | B17: 0.075271682 | C17: 0.075502956 | D17: 0.075991939 | E17: 0.076772172 | F17: 0.077772492 | G17: 0.078941668 | H17: 0.08019428 | I17: 0.081393868 | J17: 0.082367747 | K17: 0.083013865 | L17: 0.083316933 | M17: 0.083378214 | N17: 0.083319216 | O17: 0.083230616 | P17: 0.083149198 | Q17: 0.083099149 | R17: 0.083070843 | S17: 0.083060949 | T17: 0.083059226 | U17: 0.083066773

Sheet portfolios (2)
C1: Current Portfolio | E1: Target Portfolio
B2: Fixed Income | C2: 0.5 | E2: 0.40015678
B3: US Govt. Bonds | C3: 50 | E3: 40.015678
B4: Equity Index | C4: 0.5 | E4: 0.40015678
B5: Global Equity | C5: 50 | E5: 40.015678
B6: Private Equity | C6: 0 | E6: 0.15995205
B7: Buyout | C7: 0 | E7: 10.018388
B8: Growth | C8: 0 | E8: 3.9844752
B9: Venture | C9: 0 | E9: 1.9923418
B10: Other Private Assets | C10: 0 | E10: 0.039734385
B11: Private Credit | C11: 0 | E11: 3.9734385
B12: TOTAL | C12: 1 | E12: 1
C13: 0 | E13: 0
B14: Estimated Mean Return | C14: 0.053832603 | E14: 0.060889231
B15: Sharpe Ratio | C15: 0.38304714 | E15: 0.4320528
C16: 0 | E16: 0
B17: Volatility | C17: 0.075271682 | E17: 0.083066773

Sheet risk_dashboard
B1: 0 | D1: 1 | F1: 2 | H1: 3 | J1: 4 | L1: 5 | N1: 6 | P1: 7 | R1: 8 | T1: 9 | V1: 10 | X1: 11 | Z1: 12 | AB1: 13 | AD1: 14 | AF1: 15 | AH1: 16 | AJ1: 17 | AL1: 18 | AN1: 19
A2: Fixed Income | B2: 0.5 | D2: 0.49392557 | F2: 0.48209952 | H2: 0.46722918 | J2: 0.4512852 | L2: 0.43628218 | N2: 0.4233451 | P2: 0.41271508 | R2: 0.40467661 | T2: 0.39958793 | V2: 0.39744748 | X2: 0.39727756 | Z2: 0.39800772 | AB2: 0.39887028 | AD2: 0.3995999 | AF2: 0.39999807 | AH2: 0.40019903 | AJ2: 0.40024398 | AL2: 0.40023862 | AN2: 0.40015678
A3: Equity Index | B3: 0.5 | D3: 0.49392557 | F3: 0.48209952 | H3: 0.46722918 | J3: 0.4512852 | L3: 0.43628218 | N3: 0.4233451 | P3: 0.41271508 | R3: 0.40467661 | T3: 0.39958793 | V3: 0.39744748 | X3: 0.39727756 | Z3: 0.39800772 | AB3: 0.39887028 | AD3: 0.3995999 | AF3: 0.39999807 | AH3: 0.40019903 | AJ3: 0.40024398 | AL3: 0.40023862 | AN3: 0.40015678
A4: Private Equity | B4: 0 | D4: 0.0071030884 | F4: 0.021048401 | H4: 0.040389114 | J4: 0.062680884 | L4: 0.08634577 | N4: 0.10993974 | P4: 0.13152757 | R4: 0.14856284 | T4: 0.15959806 | V4: 0.16459185 | X4: 0.16544247 | Z4: 0.16430272 | AB4: 0.16272785 | AD4: 0.16131475 | AF4: 0.1604625 | AH4: 0.15998948 | AJ4: 0.15983402 | AL4: 0.15981427 | AN4: 0.15995205
A5: Other Private Assets | B5: 0 | D5: 0.0050457764 | F5: 0.014752558 | H5: 0.025152536 | J5: 0.034748725 | L5: 0.041089862 | N5: 0.043370063 | P5: 0.043042276 | R5: 0.042083943 | T5: 0.041226071 | V5: 0.0405132 | X5: 0.040002403 | Z5: 0.039681848 | AB5: 0.039531602 | AD5: 0.039485442 | AF5: 0.03954137 | AH5: 0.039612455 | AJ5: 0.039678022 | AL5: 0.03970848 | AN5: 0.039734385
B6: 0 | D6: 0 | F6: 0 | H6: 0 | J6: 0 | L6: 0 | N6: 0 | P6: 0 | R6: 0 | T6: 0 | V6: 0 | X6: 0 | Z6: 0 | AB6: 0 | AD6: 0 | AF6: 0 | AH6: 0 | AJ6: 0 | AL6: 0 | AN6: 0
B7: 0 | D7: 0 | F7: 0 | H7: 0 | J7: 0 | L7: 0 | N7: 0 | P7: 0 | R7: 0 | T7: 0 | V7: 0 | X7: 0 | Z7: 0 | AB7: 0 | AD7: 0 | AF7: 0 | AH7: 0 | AJ7: 0 | AL7: 0 | AN7: 0
A8: Estimated Mean Return | B8: 0.053832603 | D8: 0.054247291 | F8: 0.055055358 | H8: 0.056081978 | J8: 0.057191923 | L8: 0.05825228 | N8: 0.059185207 | P8: 0.05996386 | R8: 0.060555237 | T8: 0.060929042 | V8: 0.061086137 | X8: 0.061098841 | Z8: 0.061046012 | AB8: 0.060983541 | AD8: 0.060930615 | AF8: 0.060901403 | AH8: 0.060886506 | AJ8: 0.060883006 | AL8: 0.060883339 | AN8: 0.060889231
A9: Sharpe Ratio | B9: 0.38304714 | D9: 0.38736617 | F9: 0.39550719 | H9: 0.40485995 | J9: 0.41392428 | L9: 0.42122596 | N9: 0.42627987 | P9: 0.42956382 | R9: 0.43166455 | T9: 0.43280773 | V9: 0.43311888 | X9: 0.43295292 | Z9: 0.43262544 | AB9: 0.43233539 | AD9: 0.43212221 | AF9: 0.43203093 | AH9: 0.43199882 | AJ9: 0.43200814 | AL9: 0.43202111 | AN9: 0.4320528
B10: 0 | D10: 0 | F10: 0 | H10: 0 | J10: 0 | L10: 0 | N10: 0 | P10: 0 | R10: 0 | T10: 0 | V10: 0 | X10: 0 | Z10: 0 | AB10: 0 | AD10: 0 | AF10: 0 | AH10: 0 | AJ10: 0 | AL10: 0 | AN10: 0
B11: 0 | D11: 0 | F11: 0 | H11: 0 | J11: 0 | L11: 0 | N11: 0 | P11: 0 | R11: 0 | T11: 0 | V11: 0 | X11: 0 | Z11: 0 | AB11: 0 | AD11: 0 | AF11: 0 | AH11: 0 | AJ11: 0 | AL11: 0 | AN11: 0
A12: Volatility | B12: 0.075271682 | D12: 0.075502956 | F12: 0.075991939 | H12: 0.076772172 | J12: 0.077772492 | L12: 0.078941668 | N12: 0.08019428 | P12: 0.081393868 | R12: 0.082367747 | T12: 0.083013865 | V12: 0.083316933 | X12: 0.083378214 | Z12: 0.083319216 | AB12: 0.083230616 | AD12: 0.083149198 | AF12: 0.083099149 | AH12: 0.083070843 | AJ12: 0.083060949 | AL12: 0.083059226 | AN12: 0.083066773
A13: Factor Based Risk Analytics
A14: Predicted Performance Over Stress Periods | B14: Nominal | C14: Real | D14: Nominal | E14: Real | F14: Nominal | G14: Real | H14: Nominal | I14: Real | J14: Nominal | K14: Real | L14: Nominal | M14: Real | N14: Nominal | O14: Real | P14: Nominal | Q14: Real | R14: Nominal | S14: Real | T14: Nominal | U14: Real | V14: Nominal | W14: Real | X14: Nominal | Y14: Real | Z14: Nominal | AA14: Real | AB14: Nominal | AC14: Real | AD14: Nominal | AE14: Real | AF14: Nominal | AG14: Real | AH14: Nominal | AI14: Real | AJ14: Nominal | AK14: Real | AL14: Nominal | AM14: Real | AN14: Nominal | AO14: Real
A15: Bretton Woods Collapse | B15: 0.17499478 | C15: 0.11996565 | D15: 0.17551867 | E15: 0.12046501 | F15: 0.17655055 | G15: 0.12144856 | H15: 0.17803269 | I15: 0.12286129 | J15: 0.17978356 | K15: 0.12453016 | L15: 0.18171185 | M15: 0.12636815 | N15: 0.18370878 | O15: 0.12827155 | P15: 0.18558228 | Q15: 0.13005731 | R15: 0.187077 | S15: 0.13148202 | T15: 0.1880536 | U15: 0.13241289 | V15: 0.18850554 | W15: 0.13284366 | X15: 0.18859376 | Y15: 0.13292775 | Z15: 0.18850361 | AA15: 0.13284182 | AB15: 0.18837062 | AC15: 0.13271506 | AD15: 0.18824884 | AE15: 0.13259898 | AF15: 0.18817361 | AG15: 0.13252728 | AH15: 0.18813096 | AI15: 0.13248663 | AJ15: 0.18811599 | AK15: 0.13247236 | AL15: 0.1881135 | AM15: 0.13246998 | AN15: 0.18812484 | AO15: 0.13248079
A16: Oil Embargo | B16: -0.17760179 | C16: -0.30112279 | D16: -0.17747006 | E16: -0.30101085 | F16: -0.17724654 | G16: -0.30082089 | H16: -0.17742607 | I16: -0.30097346 | J16: -0.17802323 | K16: -0.30148093 | L16: -0.17927914 | M16: -0.30254821 | N16: -0.18118276 | O16: -0.30416591 | P16: -0.18331793 | Q16: -0.30598039 | R16: -0.18512896 | S16: -0.30751941 | T16: -0.18635933 | U16: -0.30856499 | V16: -0.18698887 | W16: -0.30909997 | X16: -0.18717964 | Y16: -0.30926209 | Z16: -0.18713479 | AA16: -0.30922397 | AB16: -0.18701025 | AC16: -0.30911814 | AD16: -0.18688013 | AE16: -0.30900756 | AF16: -0.18678702 | AG16: -0.30892843 | AH16: -0.18672811 | AI16: -0.30887838 | AJ16: -0.18670106 | AK16: -0.30885539 | AL16: -0.18669312 | AM16: -0.30884863 | AN16: -0.18670165 | AO16: -0.30885589
A17: US Inflation / Iranian Revolution | B17: 0.091966297 | C17: -0.079811031 | D17: 0.091604481 | E17: -0.08011593 | F17: 0.090902863 | G17: -0.080707177 | H17: 0.090066945 | I17: -0.081411596 | J17: 0.089218955 | K17: -0.082126188 | L17: 0.088508327 | M17: -0.082725027 | N17: 0.08800106 | O17: -0.083152497 | P17: 0.087659002 | Q17: -0.083440745 | R17: 0.087428658 | S17: -0.083634853 | T17: 0.087299207 | U17: -0.083743941 | V17: 0.087266819 | W17: -0.083771234 | X17: 0.087291645 | Y17: -0.083750313 | Z17: 0.087334359 | AA17: -0.083714319 | AB17: 0.087370484 | AC17: -0.083683877 | AD17: 0.087396171 | AE17: -0.08366223 | AF17: 0.087406759 | AG17: -0.083653308 | AH17: 0.087410196 | AI17: -0.083650411 | AJ17: 0.087408728 | AK17: -0.083651648 | AL17: 0.087406944 | AM17: -0.083653152 | AN17: 0.087403009 | AO17: -0.083656468
A18: US Stagflation | B18: 0.033833922 | C18: -0.092351672 | D18: 0.035026666 | E18: -0.091304509 | F18: 0.037318176 | G18: -0.089292692 | H18: 0.039727555 | I18: -0.087177392 | J18: 0.041888631 | K18: -0.085280088 | L18: 0.043187144 | M18: -0.084140066 | N18: 0.043430367 | O18: -0.08392653 | P18: 0.043015779 | Q18: -0.084290515 | R18: 0.0424868 | S18: -0.084754929 | T18: 0.042056452 | U18: -0.08513275 | V18: 0.04174943 | W18: -0.085402299 | X18: 0.041567352 | Y18: -0.085562153 | Z18: 0.041482895 | AA18: -0.085636301 | AB18: 0.041463567 | AC18: -0.08565327 | AD18: 0.041475 | AE18: -0.085643233 | AF18: 0.04150535 | AG18: -0.085616587 | AH18: 0.041533696 | AI18: -0.085591701 | AJ18: 0.04155523 | AK18: -0.085572795 | AL18: 0.041565014 | AM18: -0.085564205 | AN18: 0.041570423 | AO18: -0.085559457
A19: Black Monday | B19: -0.093805688 | C19: -0.096177114 | D19: -0.093978926 | E19: -0.0963499 | F19: -0.094331733 | G19: -0.096701783 | H19: -0.095016923 | I19: -0.09738518 | J19: -0.0959614 | K19: -0.098327186 | L19: -0.09721359 | M19: -0.099576099 | N19: -0.098726263 | O19: -0.10108481 | P19: -0.10027288 | Q19: -0.10262738 | R19: -0.10154923 | S19: -0.10390039 | T19: -0.10240477 | U19: -0.1047537 | V19: -0.10282729 | W19: -0.10517511 | X19: -0.10293903 | Y19: -0.10528655 | Z19: -0.10288874 | AA19: -0.1052364 | AB19: -0.10278957 | AC19: -0.10513748 | AD19: -0.10269196 | AE19: -0.10504014 | AF19: -0.10262672 | AG19: -0.10497506 | AH19: -0.1025873 | AI19: -0.10493575 | AJ19: -0.10257092 | AK19: -0.10491941 | AL19: -0.10256674 | AM19: -0.10491524 | AN19: -0.10257435 | AO19: -0.10492283
A20: Bond Crisis | B20: -0.031535849 | C20: -0.054164175 | D20: -0.03097959 | E20: -0.053620913 | F20: -0.029897637 | G20: -0.05256424 | H20: -0.028559579 | I20: -0.051257446 | J20: -0.027142991 | K20: -0.049873957 | L20: -0.025841834 | M20: -0.048603201 | N20: -0.024758002 | O20: -0.047544693 | P20: -0.023893908 | Q20: -0.046700789 | R20: -0.023248819 | S20: -0.046070773 | T20: -0.022842999 | U20: -0.045674434 | V20: -0.02267588 | W20: -0.045511221 | X20: -0.022667279 | Y20: -0.04550282 | Z20: -0.02273024 | AA20: -0.04556431 | AB20: -0.022802322 | AC20: -0.045634709 | AD20: -0.022862472 | AE20: -0.045693452 | AF20: -0.022894358 | AG20: -0.045724594 | AH20: -0.022909962 | AI20: -0.045739834 | AJ20: -0.022912887 | AK20: -0.04574269 | AL20: -0.02291212 | AM20: -0.045741941 | AN20: -0.022905145 | AO20: -0.045735129
A21: Russian Default / LTCM Collapse | B21: -0.067084778 | C21: -0.068230254 | D21: -0.067746087 | E21: -0.068890751 | F21: -0.06904181 | G21: -0.070184883 | H21: -0.070794213 | I21: -0.071935134 | J21: -0.072782778 | K21: -0.073921257 | L21: -0.074844398 | M21: -0.075980346 | N21: -0.076848264 | O21: -0.077981752 | P21: -0.078651391 | Q21: -0.079782664 | R21: -0.080066463 | S21: -0.081195999 | T21: -0.080981942 | U21: -0.082110354 | V21: -0.081394386 | W21: -0.082522292 | X21: -0.081462228 | Y21: -0.082590051 | Z21: -0.081364536 | AA21: -0.082492479 | AB21: -0.08123131 | AC21: -0.082359416 | AD21: -0.081112343 | AE21: -0.082240595 | AF21: -0.081041506 | AG21: -0.082169845 | AH21: -0.081002606 | AI21: -0.082130992 | AJ21: -0.080990253 | AK21: -0.082118655 | AL21: -0.080988854 | AM21: -0.082117258 | AN21: -0.081000647 | AO21: -0.082129036
A22: Tech Meltdown | B22: -0.18876721 | C22: -0.23274034 | D22: -0.18748385 | E22: -0.23152655 | F22: -0.18504208 | G22: -0.22921713 | H22: -0.18280143 | I22: -0.22709794 | J22: -0.18113614 | K22: -0.22552291 | L22: -0.18084034 | M22: -0.22524315 | N22: -0.18209413 | O22: -0.22642897 | P22: -0.18417969 | Q22: -0.22840149 | R22: -0.18612696 | S22: -0.23024321 | T22: -0.18752235 | U22: -0.23156296 | V22: -0.18832194 | W22: -0.23231921 | X22: -0.18865091 | Y22: -0.23263034 | Z22: -0.18869712 | AA22: -0.23267405 | AB22: -0.18861667 | AC22: -0.23259796 | AD22: -0.18850204 | AE22: -0.23248954 | AF22: -0.18839864 | AG22: -0.23239175 | AH22: -0.18832438 | AI22: -0.23232151 | AJ22: -0.18828203 | AK22: -0.23228145 | AL22: -0.1882662 | AM22: -0.23226648 | AN22: -0.18826773 | AO22: -0.23226793
A23: Financial Crisis | B23: -0.25987242 | C23: -0.27210456 | D23: -0.26175075 | E23: -0.27395184 | F23: -0.26544179 | G23: -0.27758187 | H23: -0.27059409 | I23: -0.28264902 | J23: -0.27655726 | K23: -0.28851364 | L23: -0.28292294 | M23: -0.29477412 | N23: -0.28929903 | O23: -0.30104483 | P23: -0.29514336 | Q23: -0.30679257 | R23: -0.2997574 | S23: -0.31133035 | T23: -0.30275664 | U23: -0.31428003 | V23: -0.30413321 | W23: -0.31563384 | X23: -0.30439045 | Y23: -0.31588683 | Z23: -0.30410078 | AA23: -0.31560195 | AB23: -0.30368332 | AC23: -0.31519139 | AD23: -0.30330392 | AE23: -0.31481825 | AF23: -0.30307296 | AG23: -0.31459112 | AH23: -0.30294358 | AI23: -0.31446387 | AJ23: -0.30289974 | AK23: -0.31442076 | AL23: -0.30289307 | AM23: -0.3144142 | AN23: -0.30292921 | AO23: -0.31444974
A24: Covid-19 | B24: -0.089207424 | C24: -0.085983284 | D24: -0.090122342 | E24: -0.086901441 | F24: -0.091915179 | G24: -0.088700624 | H24: -0.094343379 | I24: -0.09113742 | J24: -0.0970978 | K24: -0.093901591 | L24: -0.099950011 | M24: -0.096763899 | N24: -0.10271811 | O24: -0.099541794 | P24: -0.10520705 | Q24: -0.10203955 | R24: -0.10716193 | S24: -0.10400134 | T24: -0.10842973 | U24: -0.10527364 | V24: -0.10900416 | W24: -0.1058501 | X24: -0.10910177 | Y24: -0.10594805 | Z24: -0.10896883 | AA24: -0.10581465 | AB24: -0.10878538 | AC24: -0.10563055 | AD24: -0.10862102 | AE24: -0.10546561 | AF24: -0.10852301 | AG24: -0.10536725 | AH24: -0.10846908 | AI24: -0.10531312 | AJ24: -0.10845181 | AK24: -0.1052958 | AL24: -0.10844971 | AM24: -0.10529368 | AN24: -0.10846589 | AO24: -0.10530992
A25: Value at Risk with 99% Confidence
A26: Over 1 Month | B26: 0.054812288 | C26: 0.056812134 | D26: 0.054949302 | E26: 0.056948858 | F26: 0.055321997 | G26: 0.057320764 | H26: 0.055966792 | I26: 0.057964195 | J26: 0.056879331 | K26: 0.058874803 | L26: 0.057860547 | M26: 0.059853943 | N26: 0.058878053 | O26: 0.060869297 | P26: 0.060112073 | Q26: 0.062100705 | R26: 0.061267882 | S26: 0.063254069 | T26: 0.062060365 | U26: 0.064044875 | V26: 0.062323862 | W26: 0.064307815 | X26: 0.062361208 | Y26: 0.064345081 | Z26: 0.062301912 | AA26: 0.064285911 | AB26: 0.062252402 | AC26: 0.064236506 | AD26: 0.062128321 | AE26: 0.064112687 | AF26: 0.062057351 | AG26: 0.064041868 | AH26: 0.062019842 | AI26: 0.064004438 | AJ26: 0.062009503 | AK26: 0.063994121 | AL26: 0.062009213 | AM26: 0.063993831 | AN26: 0.062022329 | AO26: 0.06400692
A27: Over 1 Year | B27: 0.16290504 | C27: 0.18298147 | D27: 0.16469933 | E27: 0.18464587 | F27: 0.16746838 | G27: 0.18774951 | H27: 0.17304647 | I27: 0.1926658 | J27: 0.17852557 | K27: 0.19762213 | L27: 0.18427605 | M27: 0.20328693 | N27: 0.19005946 | O27: 0.20946344 | P27: 0.19566009 | Q27: 0.2145538 | R27: 0.20037387 | S27: 0.21818461 | T27: 0.20285789 | U27: 0.22044188 | V27: 0.20387933 | W27: 0.2218649 | X27: 0.20407445 | Y27: 0.22207702 | Z27: 0.20386458 | AA27: 0.22171345 | AB27: 0.20355881 | AC27: 0.22123364 | AD27: 0.20328001 | AE27: 0.22081003 | AF27: 0.20310911 | AG27: 0.22058812 | AH27: 0.20301291 | AI27: 0.22047068 | AJ27: 0.20297988 | AK27: 0.22043342 | AL27: 0.20297464 | AM27: 0.22042917 | AN27: 0.20300102 | AO27: 0.22046481
A28: Over 3 Years | B28: 0.19491784 | C28: 0.24811812 | D28: 0.19522226 | E28: 0.24829725 | F28: 0.19614599 | G28: 0.24726973 | H28: 0.19727903 | I28: 0.24914364 | J28: 0.19977176 | K28: 0.25058148 | L28: 0.20334193 | M28: 0.25496085 | N28: 0.20770168 | O28: 0.25935618 | P28: 0.21259222 | Q28: 0.26310094 | R28: 0.21562015 | S28: 0.26584083 | T28: 0.21823396 | U28: 0.26757358 | V28: 0.21897567 | W28: 0.268618 | X28: 0.21916537 | Y28: 0.26886855 | Z28: 0.21906914 | AA28: 0.26859993 | AB28: 0.21888557 | AC28: 0.26837796 | AD28: 0.21870672 | AE28: 0.26818934 | AF28: 0.21858939 | AG28: 0.26806169 | AH28: 0.21851968 | AI28: 0.26798382 | AJ28: 0.21847612 | AK28: 0.26795069 | AL28: 0.21846864 | AM28: 0.26794164 | AN28: 0.21849979 | AO28: 0.26795575
A29: Conditional Value at Risk with 99% Confidence
A30: Over 1 Month | B30: 0.072489474 | C30: 0.074451918 | D30: 0.072954744 | E30: 0.074916204 | F30: 0.073920562 | G30: 0.075879978 | H30: 0.07535398 | I30: 0.077310364 | J30: 0.077103936 | K30: 0.079056616 | L30: 0.079030066 | M30: 0.080978672 | N30: 0.080990396 | O30: 0.082934854 | P30: 0.082843945 | Q30: 0.08478448 | R30: 0.084345085 | S30: 0.086282445 | T30: 0.085327056 | U30: 0.087262338 | V30: 0.085771617 | W30: 0.087705958 | X30: 0.085845695 | Y30: 0.087779879 | Z30: 0.085740573 | AA30: 0.08767498 | AB30: 0.085597157 | AC30: 0.087531868 | AD30: 0.085469371 | AE30: 0.087404352 | AF30: 0.085393368 | AG30: 0.087328509 | AH30: 0.085351653 | AI30: 0.087286883 | AJ30: 0.085338423 | AK30: 0.087273681 | AL30: 0.085336892 | AM30: 0.087272153 | AN30: 0.085349545 | AO30: 0.08728478
A31: Over 1 Year | B31: 0.19916394 | C31: 0.21734289 | D31: 0.20088029 | E31: 0.21905044 | F31: 0.20435916 | G31: 0.22247102 | H31: 0.20922194 | I31: 0.22727567 | J31: 0.2149148 | K31: 0.23283831 | L31: 0.22094081 | M31: 0.23869018 | N31: 0.22686085 | O31: 0.24447435 | P31: 0.23228647 | Q31: 0.24975353 | R31: 0.2365967 | S31: 0.25391965 | T31: 0.23940551 | U31: 0.25666199 | V31: 0.24068104 | W31: 0.25790705 | X31: 0.24090201 | Y31: 0.25812297 | Z31: 0.24061216 | AA31: 0.25784032 | AB31: 0.24020863 | AC31: 0.25744663 | AD31: 0.23984589 | AE31: 0.2570927 | AF31: 0.23962873 | AG31: 0.25688076 | AH31: 0.23950882 | AI31: 0.25676372 | AJ31: 0.23947004 | AK31: 0.25672585 | AL31: 0.23946509 | AM31: 0.256721 | AN31: 0.23950062 | AO31: 0.25675565
A32: Over 3 Years | B32: 0.24397112 | C32: 0.29170717 | D32: 0.24431179 | E32: 0.29206846 | F32: 0.24521329 | G32: 0.29299172 | H32: 0.24738562 | I32: 0.29499413 | J32: 0.25062787 | K32: 0.29795271 | L32: 0.2548015 | M32: 0.30182843 | N32: 0.25976223 | O32: 0.30635335 | P32: 0.26466034 | Q32: 0.31088111 | R32: 0.26875539 | S32: 0.31468592 | T32: 0.27151906 | U32: 0.31721374 | V32: 0.27282857 | W32: 0.31841561 | X32: 0.27311465 | Y32: 0.31868212 | Z32: 0.2728869 | AA32: 0.31847678 | AB32: 0.27252467 | AC32: 0.3181488 | AD32: 0.27218594 | AE32: 0.31784095 | AF32: 0.27197306 | AG32: 0.31764668 | AH32: 0.27185051 | AI32: 0.31753444 | AJ32: 0.27180557 | AK32: 0.31749282 | AL32: 0.27179664 | AM32: 0.31748435 | AN32: 0.27182684 | AO32: 0.31751163
A33: Probability of Loss
A34: Over 1 Month | B34: 0.35245 | C34: 0.392 | D34: 0.35185 | E34: 0.39095 | F34: 0.35015 | G34: 0.38925 | H34: 0.34895 | I34: 0.3869 | J34: 0.34715 | K34: 0.3852 | L34: 0.3459 | M34: 0.38335 | N34: 0.3464 | O34: 0.38125 | P34: 0.34675 | Q34: 0.3807 | R34: 0.34635 | S34: 0.3805 | T34: 0.3463 | U34: 0.3802 | V34: 0.3464 | W34: 0.3796 | X34: 0.34645 | Y34: 0.3797 | Z34: 0.34655 | AA34: 0.38 | AB34: 0.3465 | AC34: 0.38015 | AD34: 0.34655 | AE34: 0.38025 | AF34: 0.3466 | AG34: 0.38025 | AH34: 0.34665 | AI34: 0.38025 | AJ34: 0.34665 | AK34: 0.38025 | AL34: 0.34665 | AM34: 0.38025 | AN34: 0.3466 | AO34: 0.38025
A35: Over 1 Year | B35: 0.1939 | C35: 0.2672 | D35: 0.1933 | E35: 0.26625 | F35: 0.19255 | G35: 0.26395 | H35: 0.1911 | I35: 0.26175 | J35: 0.18995 | K35: 0.26015 | L35: 0.1898 | M35: 0.2582 | N35: 0.19045 | O35: 0.25775 | P35: 0.19155 | Q35: 0.25725 | R35: 0.19185 | S35: 0.25705 | T35: 0.19265 | U35: 0.2579 | V35: 0.1932 | W35: 0.2582 | X35: 0.1934 | Y35: 0.25835 | Z35: 0.19335 | AA35: 0.2584 | AB35: 0.1932 | AC35: 0.2582 | AD35: 0.19305 | AE35: 0.2582 | AF35: 0.19305 | AG35: 0.25805 | AH35: 0.19305 | AI35: 0.25795 | AJ35: 0.193 | AK35: 0.25795 | AL35: 0.193 | AM35: 0.25795 | AN35: 0.19305 | AO35: 0.25805
A36: Over 3 Years | B36: 0.1171 | C36: 0.20125 | D36: 0.11655 | E36: 0.2001 | F36: 0.11595 | G36: 0.1992 | H36: 0.11485 | I36: 0.19755 | J36: 0.1142 | K36: 0.19575 | L36: 0.1141 | M36: 0.19455 | N36: 0.1149 | O36: 0.19365 | P36: 0.1154 | Q36: 0.19355 | R36: 0.1166 | S36: 0.19315 | T36: 0.11705 | U36: 0.19375 | V36: 0.11735 | W36: 0.19405 | X36: 0.1174 | Y36: 0.19415 | Z36: 0.1173 | AA36: 0.19415 | AB36: 0.11735 | AC36: 0.19425 | AD36: 0.1174 | AE36: 0.1942 | AF36: 0.11735 | AG36: 0.19405 | AH36: 0.1173 | AI36: 0.194 | AJ36: 0.1173 | AK36: 0.194 | AL36: 0.1173 | AM36: 0.194 | AN36: 0.1173 | AO36: 0.194
A37: Portfolio Risk Premia

Sheet assumptions
B1: Long-Term Estimates | I1: Modelling Dates
B2: Risk Premia with Estimated Range | E2: Volatility | F2: Sharpe Ratio | G2: Estimated Mean Return (2.5% Risk Free Rate) | H2: Hedging Ratio | I2: From | J2: To
A3: Fixed Income
A4: Bloomberg U.S. Treasury: Intermediate USD | B4: 0.0057327167 | C4: 0.010867352 | D4: 0.016001987 | E4: 0.03211081 | F4: 0.33843281 | G4: 0.035867352 | H4: 0 | I4: 26723 | J4: 45777
A5: Equity Index
A6: MSCI All Country World | B6: 0.021506435 | C6: 0.046797853 | D6: 0.072089271 | E6: 0.14950309 | F6: 0.31302265 | G6: 0.071797853 | H6: 0 | I6: 32171 | J6: 45777
A7: Private Equity
A8: Buyout | B8: 0.018093277 | C8: 0.065301868 | D8: 0.11251046 | E8: 0.13777198 | F8: 0.4739851 | G8: 0.090301868 | H8: 0 | I8: 25598 | J8: 45777
A9: Growth | B9: 0.013496497 | C9: 0.067090636 | D9: 0.12068477 | E9: 0.15640736 | F9: 0.42894808 | G9: 0.092090636 | H9: 0 | I9: 28886 | J9: 45777
A10: Venture | B10: 0.0048618709 | C10: 0.062172068 | D10: 0.11948227 | E10: 0.16725218 | F10: 0.3717265 | G10: 0.087172068 | H10: 0 | I10: 30680 | J10: 44925
A11: Other Private Assets
A12: Private Credit | B12: 0.020469028 | C12: 0.059395007 | D12: 0.098320985 | E12: 0.11360029 | F12: 0.52284206 | G12: 0.084395007 | H12: 0 | I12: 30589 | J12: 45777

Sheet ws_0
B1: nominal | C1: nominal | D1: nominal | E1: nominal
B2: 1st %ile | C2: 10th %ile | D2: 50th %ile | E2: 90th %ile
A3: 0 | B3: 100 | C3: 100 | D3: 100 | E3: 100 | F3: 100 | G3: =D3 -> 100
A4: 1 | B4: 88.24945 | C4: 96.603441 | D4: 107.23708 | E4: 116.97168 | F4: 107.76189 | G4: =D4 -> 107.23708
A5: 2 | B5: 88.403588 | C5: 98.936711 | D5: 113.61221 | E5: 128.82299 | F5: 115.1037 | G5: =D5 -> 113.61221
A6: 3 | B6: 89.777364 | C6: 102.72435 | D6: 120.44927 | E6: 140.42639 | F6: 122.66626 | G6: =D6 -> 120.44927
A7: 4 | B7: 89.873321 | C7: 106.25824 | D7: 128.55142 | E7: 153.85681 | F7: 131.57689 | G7: =D7 -> 128.55142
A8: 5 | B8: 91.129085 | C8: 110.59648 | D8: 137.45634 | E8: 168.64525 | F8: 141.15344 | G8: =D8 -> 137.45634
A9: 6 | B9: 92.40512 | C9: 115.28638 | D9: 146.82714 | E9: 183.99708 | F9: 151.08353 | G9: =D9 -> 146.82714
A10: 7 | B10: 91.359429 | C10: 118.77811 | D10: 156.58113 | E10: 201.21546 | F10: 161.18185 | G10: =D10 -> 156.58113
A11: 8 | B11: 92.232909 | C11: 122.58916 | D11: 166.48807 | E11: 219.21235 | F11: 171.51312 | G11: =D11 -> 166.48807
A12: 9 | B12: 92.071467 | C12: 126.00884 | D12: 176.78313 | E12: 238.90347 | F12: 182.10309 | G12: =D12 -> 176.78313
A13: 10 | B13: 93.071326 | C13: 130.0263 | D13: 187.40441 | E13: 259.20597 | F13: 193.01279 | G13: =D13 -> 187.40441
A14: 11 | B14: 94.47886 | C14: 134.25015 | D14: 198.44747 | E14: 281.13905 | F14: 204.54726 | G14: =D14 -> 198.44747
... A23: 20 | B23: 113.18667 | C23: 186.10105 | D23: 330.15274 | E23: 564.15742 | F23: 340.17719 | G23: =D23 -> 330.15274
O29: 0 | P29: 1 | Q29: 2 | R29: 3
N30: 0 | O30: 100 | P30: 100 | Q30: 100 | R30: 100
F31: 0 | G31: 1 | H31: 2 | I31: 3 | N31: 1 | O31: 87.934593 | P31: 96.910974 | Q31: 107.76189 | R31: 118.64253
E32: 0 | F32: 100 | G32: 100 | H32: 100 | I32: 100 | N32: 2 | O32: 88.65842 | P32: 99.516262 | Q32: 115.1037 | R32: 131.35942
E33: 1 | F33: 88.24945 | G33: 96.603441 | H33: 107.23708 | I33: 116.97168 | N33: 3 | O33: 90.269658 | P33: 103.99879 | Q33: 122.66626 | R33: 143.84673
E34: 2 | F34: 88.403588 | G34: 98.936711 | H34: 113.61221 | I34: 128.82299 | N34: 4 | O34: 90.109603 | P34: 107.65032 | Q34: 131.57689 | R34: 158.83901
E35: 3 | F35: 89.777364 | G35: 102.72435 | H35: 120.44927 | I35: 140.42639 | N35: 5 | O35: 91.460082 | P35: 112.36301 | Q35: 141.15344 | R35: 174.82357
E36: 4 | F36: 89.873321 | G36: 106.25824 | H36: 128.55142 | I36: 153.85681 | N36: 6 | O36: 92.607044 | P36: 116.94991 | Q36: 151.08353 | R36: 191.29927
E37: 5 | F37: 91.129085 | G37: 110.59648 | H37: 137.45634 | I37: 168.64525 | N37: 7 | O37: 91.645526 | P37: 121.07303 | Q37: 161.18185 | R37: 209.79786
E38: 6 | F38: 92.40512 | G38: 115.28638 | H38: 146.82714 | I38: 183.99708 | N38: 8 | O38: 92.544986 | P38: 124.73673 | Q38: 171.51312 | R38: 228.43665
E39: 7 | F39: 91.359429 | G39: 118.77811 | H39: 156.58113 | I39: 201.21546 | N39: 9 | O39: 92.585965 | P39: 128.49745 | Q39: 182.10309 | R39: 249.401
E40: 8 | F40: 92.232909 | G40: 122.58916 | H40: 166.48807 | I40: 219.21235 | N40: 10 | O40: 93.704215 | P40: 132.64997 | Q40: 193.01279 | R40: 269.93231
E41: 9 | F41: 92.071467 | G41: 126.00884 | H41: 176.78313 | I41: 238.90347 | N41: 11 | O41: 94.905133 | P41: 136.89025 | Q41: 204.54726 | R41: 292.1415
E42: 10 | F42: 93.071326 | G42: 130.0263 | H42: 187.40441 | I42: 259.20597 | N42: 12 | O42: 97.644783 | P42: 141.87574 | Q42: 215.78344 | R42: 318.19655
E43: 11 | F43: 94.47886 | G43: 134.25015 | H43: 198.44747 | I43: 281.13905 | N43: 13 | O43: 98.539086 | P43: 146.44892 | Q43: 229.16677 | R43: 343.77081
... E50: 18 | F50: 107.80174 | G50: 172.06826 | H50: 294.9108 | I50: 489.18037 | N50: 20 | O50: 114.69824 | P50: 190.96446 | Q50: 340.17719 | R50: 585.3413
E51: 19 | F51: 110.12868 | G51: 179.41175 | H51: 312.22668 | I51: 525.68105
E52: 20 | F52: 113.18667 | G52: 186.10105 | H52: 330.15274 | I52: 564.15742

Sheet ws_1
B1: nominal | C1: nominal | D1: nominal | E1: nominal | F1: real | G1: real | H1: real | I1: real | J1: net_flows | K1: net_flows | L1: net_flows | M1: net_flows | N1: real_net_flows | O1: real_net_flows | P1: real_net_flows | Q1: real_net_flows
B2: 1st %ile | C2: 10th %ile | D2: 50th %ile | E2: 90th %ile | F2: 1st %ile | G2: 10th %ile | H2: 50th %ile | I2: 90th %ile | J2: 1st %ile | K2: 10th %ile | L2: 50th %ile | M2: 90th %ile | N2: 1st %ile | O2: 10th %ile | P2: 50th %ile | Q2: 90th %ile
A3: 0 | B3: 100 | C3: 100 | D3: 100 | E3: 100 | F3: 100 | G3: 100 | H3: 100 | I3: 100 | J3: 0 | K3: 0 | L3: 0 | M3: 0 | N3: 0 | O3: 0 | P3: 0 | Q3: 0
A4: 1 | B4: 88.260754 | C4: 96.66644 | D4: 107.26951 | E4: 117.05552 | F4: 85.444034 | G4: 94.244107 | H4: 104.90866 | I4: 114.63005 | J4: 0 | K4: 0 | L4: 0 | M4: 0 | N4: 0 | O4: 0 | P4: 0 | Q4: 0
A5: 2 | B5: 88.455306 | C5: 98.977248 | D5: 113.64133 | E5: 128.86512 | F5: 83.683167 | G5: 94.159988 | H5: 108.57266 | I5: 123.51287 | J5: 0 | K5: 0 | L5: 0 | M5: 0 | N5: 0 | O5: 0 | P5: 0 | Q5: 0
A6: 3 | B6: 89.741153 | C6: 102.70215 | D6: 120.40994 | E6: 140.31247 | F6: 82.718766 | G6: 95.637179 | H6: 112.51533 | I6: 131.72651 | J6: 0 | K6: 0 | L6: 0 | M6: 0 | N6: 0 | O6: 0 | P6: 0 | Q6: 0
A7: 4 | B7: 89.809153 | C7: 106.03113 | D7: 128.23506 | E7: 153.46649 | F7: 81.356931 | G7: 96.55993 | H7: 117.37364 | I7: 140.97958 | J7: 0 | K7: 0 | L7: 0 | M7: 0 | N7: 0 | O7: 0 | P7: 0 | Q7: 0
A8: 5 | B8: 90.979454 | C8: 110.29935 | D8: 136.75448 | E8: 167.50685 | F8: 80.667209 | G8: 98.108483 | H8: 122.50537 | I8: 150.83022 | J8: 0 | K8: 0 | L8: 0 | M8: 0 | N8: 0 | O8: 0 | P8: 0 | Q8: 0
A9: 6 | B9: 92.350678 | C9: 114.62351 | D9: 145.53186 | E9: 181.89119 | F9: 80.494027 | G9: 99.748482 | H9: 127.6401 | I9: 160.36704 | J9: 0 | K9: 0 | L9: 0 | M9: 0 | N9: 0 | O9: 0 | P9: 0 | Q9: 0
A10: 7 | B10: 91.931916 | C10: 117.78138 | D10: 154.32788 | E10: 197.53216 | F10: 78.008612 | G10: 100.65334 | H10: 132.6841 | I10: 170.45838 | J10: 0 | K10: 0 | L10: 0 | M10: 0 | N10: 0 | O10: 0 | P10: 0 | Q10: 0
A11: 8 | B11: 91.916103 | C11: 121.41945 | D11: 163.29802 | E11: 213.36388 | F11: 77.707135 | G11: 101.8415 | H11: 137.33521 | I11: 180.62774 | J11: 0 | K11: 0 | L11: 0 | M11: 0 | N11: 0 | O11: 0 | P11: 0 | Q11: 0
A12: 9 | B12: 92.292191 | C12: 124.41913 | D12: 172.47553 | E12: 230.2999 | F12: 75.879431 | G12: 102.10016 | H12: 142.21119 | I12: 191.2829 | J12: 0 | K12: 0 | L12: 0 | M12: 0 | N12: 0 | O12: 0 | P12: 0 | Q12: 0
A13: 10 | B13: 93.418377 | C13: 128.15293 | D13: 181.71173 | E13: 247.87286 | F13: 75.574283 | G13: 103.25172 | H13: 146.7706 | I13: 202.12081 | J13: 0 | K13: 0 | L13: 0 | M13: 0 | N13: 0 | O13: 0 | P13: 0 | Q13: 0
A14: 11 | B14: 94.73524 | C14: 131.64662 | D14: 191.51877 | E14: 266.62303 | F14: 75.113588 | G14: 104.16306 | H14: 151.7032 | I14: 212.84018 | J14: 0 | K14: 0 | L14: 0 | M14: 0 | N14: 0 | O14: 0 | P14: 0 | Q14: 0
... A23: 20 | B23: 110.43965 | C23: 176.6253 | D23: 301.2794 | E23: 500.37572 | F23: 74.645668 | G23: 116.71224 | H23: 200.77474 | I23: 332.54935 | J23: 0 | K23: 0 | L23: 0 | M23: 0 | N23: 0 | O23: 0 | P23: 0 | Q23: 0

Sheet ws_2
B1: nominal | C1: nominal | D1: nominal | E1: nominal | F1: real | G1: real | H1: real | I1: real | J1: net_flows | K1: net_flows | L1: net_flows | M1: net_flows | N1: real_net_flows | O1: real_net_flows | P1: real_net_flows | Q1: real_net_flows
B2: 1st %ile | C2: 10th %ile | D2: 50th %ile | E2: 90th %ile | F2: 1st %ile | G2: 10th %ile | H2: 50th %ile | I2: 90th %ile | J2: 1st %ile | K2: 10th %ile | L2: 50th %ile | M2: 90th %ile | N2: 1st %ile | O2: 10th %ile | P2: 50th %ile | Q2: 90th %ile
A3: 0 | B3: 100 | C3: 100 | D3: 100 | E3: 100 | F3: 100 | G3: 100 | H3: 100 | I3: 100 | J3: 0 | K3: 0 | L3: 0 | M3: 0 | N3: 0 | O3: 0 | P3: 0 | Q3: 0
A4: 1 | B4: 88.301857 | C4: 96.794753 | D4: 107.32665 | E4: 117.18356 | F4: 85.468108 | G4: 94.311195 | H4: 104.97567 | I4: 114.78725 | J4: 0 | K4: 0 | L4: 0 | M4: 0 | N4: 0 | O4: 0 | P4: 0 | Q4: 0
A5: 2 | B5: 88.593592 | C5: 99.184897 | D5: 113.83215 | E5: 129.12801 | F5: 83.800539 | G5: 94.286062 | H5: 108.76572 | I5: 123.75826 | J5: 0 | K5: 0 | L5: 0 | M5: 0 | N5: 0 | O5: 0 | P5: 0 | Q5: 0
A6: 3 | B6: 89.886599 | C6: 102.97469 | D6: 120.73515 | E6: 140.59286 | F6: 82.945161 | G6: 95.912598 | H6: 112.83126 | I6: 132.07555 | J6: 0 | K6: 0 | L6: 0 | M6: 0 | N6: 0 | O6: 0 | P6: 0 | Q6: 0
A7: 4 | B7: 90.119744 | C7: 106.44685 | D7: 128.71166 | E7: 153.99696 | F7: 81.63567 | G7: 96.864754 | H7: 117.78733 | I7: 141.53177 | J7: 0 | K7: 0 | L7: 0 | M7: 0 | N7: 0 | O7: 0 | P7: 0 | Q7: 0
A8: 5 | B8: 91.345763 | C8: 110.72692 | D8: 137.36176 | E8: 168.21538 | F8: 81.025304 | G8: 98.485371 | H8: 123.05189 | I8: 151.48484 | J8: 0 | K8: 0 | L8: 0 | M8: 0 | N8: 0 | O8: 0 | P8: 0 | Q8: 0
A9: 6 | B9: 92.776289 | C9: 115.09234 | D9: 146.267 | E9: 182.81687 | F9: 80.664834 | G9: 100.28294 | H9: 128.26829 | I9: 161.14975 | J9: 0 | K9: 0 | L9: 0 | M9: 0 | N9: 0 | O9: 0 | P9: 0 | Q9: 0
A10: 7 | B10: 92.489162 | C10: 118.30273 | D10: 155.2257 | E10: 198.74542 | F10: 78.338832 | G10: 101.14423 | H10: 133.42722 | I10: 171.47653 | J10: 0 | K10: 0 | L10: 0 | M10: 0 | N10: 0 | O10: 0 | P10: 0 | Q10: 0
A11: 8 | B11: 92.497392 | C11: 122.0903 | D11: 164.41365 | E11: 214.88383 | F11: 78.349944 | G11: 102.37134 | H11: 138.22231 | I11: 181.98917 | J11: 0 | K11: 0 | L11: 0 | M11: 0 | N11: 0 | O11: 0 | P11: 0 | Q11: 0
A12: 9 | B12: 92.566622 | C12: 125.2098 | D12: 173.69559 | E12: 232.36268 | F12: 76.212562 | G12: 102.79901 | H12: 143.27023 | I12: 193.01681 | J12: 0 | K12: 0 | L12: 0 | M12: 0 | N12: 0 | O12: 0 | P12: 0 | Q12: 0
A13: 10 | B13: 93.932133 | C13: 129.08195 | D13: 183.29795 | E13: 250.02389 | F13: 75.86483 | G13: 103.90449 | H13: 147.96059 | I13: 203.97837 | J13: 0 | K13: 0 | L13: 0 | M13: 0 | N13: 0 | O13: 0 | P13: 0 | Q13: 0
A14: 11 | B14: 95.229852 | C14: 132.63612 | D14: 193.20623 | E14: 269.30412 | F14: 75.648096 | G14: 105.13048 | H14: 153.01028 | I14: 214.92807 | J14: 0 | K14: 0 | L14: 0 | M14: 0 | N14: 0 | O14: 0 | P14: 0 | Q14: 0
... A23: 20 | B23: 112.09521 | C23: 178.86406 | D23: 306.2841 | E23: 509.96009 | F23: 75.490743 | G23: 118.40683 | H23: 203.85608 | I23: 338.5171 | J23: 0 | K23: 0 | L23: 0 | M23: 0 | N23: 0 | O23: 0 | P23: 0 | Q23: 0

Sheet ws_3
B1: nominal | C1: nominal | D1: nominal | E1: nominal | F1: real | G1: real | H1: real | I1: real | J1: net_flows | K1: net_flows | L1: net_flows | M1: net_flows | N1: real_net_flows | O1: real_net_flows | P1: real_net_flows | Q1: real_net_flows
B2: 1st %ile | C2: 10th %ile | D2: 50th %ile | E2: 90th %ile | F2: 1st %ile | G2: 10th %ile | H2: 50th %ile | I2: 90th %ile | J2: 1st %ile | K2: 10th %ile | L2: 50th %ile | M2: 90th %ile | N2: 1st %ile | O2: 10th %ile | P2: 50th %ile | Q2: 90th %ile
A3: 0 | B3: 100 | C3: 100 | D3: 100 | E3: 100 | F3: 100 | G3: 100 | H3: 100 | I3: 100 | J3: 0 | K3: 0 | L3: 0 | M3: 0 | N3: 0 | O3: 0 | P3: 0 | Q3: 0
A4: 1 | B4: 88.350624 | C4: 96.912658 | D4: 107.39946 | E4: 117.39674 | F4: 85.475921 | G4: 94.398333 | H4: 105.07076 | I4: 115.00668 | J4: 0 | K4: 0 | L4: 0 | M4: 0 | N4: 0 | O4: 0 | P4: 0 | Q4: 0
A5: 2 | B5: 88.740223 | C5: 99.371398 | D5: 114.08246 | E5: 129.48868 | F5: 83.971799 | G5: 94.448295 | H5: 109.02431 | I5: 124.06233 | J5: 0 | K5: 0 | L5: 0 | M5: 0 | N5: 0 | O5: 0 | P5: 0 | Q5: 0
A6: 3 | B6: 90.085417 | C6: 103.35383 | D6: 121.1399 | E6: 141.1469 | F6: 83.179083 | G6: 96.188205 | H6: 113.19263 | I6: 132.50437 | J6: 0 | K6: 0 | L6: 0 | M6: 0 | N6: 0 | O6: 0 | P6: 0 | Q6: 0
A7: 4 | B7: 90.292305 | C7: 106.86363 | D7: 129.26509 | E7: 154.7324 | F7: 81.949551 | G7: 97.18822 | H7: 118.28285 | I7: 142.19044 | J7: 0 | K7: 0 | L7: 0 | M7: 0 | N7: 0 | O7: 0 | P7: 0 | Q7: 0
A8: 5 | B8: 91.65761 | C8: 111.21834 | D8: 138.17932 | E8: 169.30427 | F8: 81.367496 | G8: 98.962731 | H8: 123.67896 | I8: 152.36562 | J8: 0 | K8: 0 | L8: 0 | M8: 0 | N8: 0 | O8: 0 | P8: 0 | Q8: 0
A9: 6 | B9: 93.19733 | C9: 115.69673 | D9: 147.15587 | E9: 184.07594 | F9: 80.940849 | G9: 100.7974 | H9: 129.05318 | I9: 162.27639 | J9: 0 | K9: 0 | L9: 0 | M9: 0 | N9: 0 | O9: 0 | P9: 0 | Q9: 0
A10: 7 | B10: 92.783504 | C10: 119.11493 | D10: 156.40543 | E10: 200.42924 | F10: 78.591883 | G10: 101.72731 | H10: 134.35035 | I10: 173.02967 | J10: 0 | K10: 0 | L10: 0 | M10: 0 | N10: 0 | O10: 0 | P10: 0 | Q10: 0
A11: 8 | B11: 93.011712 | C11: 122.86389 | D11: 165.71181 | E11: 216.95139 | F11: 78.552279 | G11: 102.93665 | H11: 139.55559 | I11: 183.79396 | J11: 0 | K11: 0 | L11: 0 | M11: 0 | N11: 0 | O11: 0 | P11: 0 | Q11: 0
A12: 9 | B12: 93.16621 | C12: 126.10541 | D12: 175.4098 | E12: 235.07267 | F12: 76.50382 | G12: 103.55127 | H12: 144.46167 | I12: 195.27316 | J12: 0 | K12: 0 | L12: 0 | M12: 0 | N12: 0 | O12: 0 | P12: 0 | Q12: 0
A13: 10 | B13: 94.342462 | C13: 130.1053 | D13: 185.05969 | E13: 252.86768 | F13: 76.185641 | G13: 104.74498 | H13: 149.51091 | I13: 206.3123 | J13: 0 | K13: 0 | L13: 0 | M13: 0 | N13: 0 | O13: 0 | P13: 0 | Q13: 0
A14: 11 | B14: 95.671797 | C14: 133.81015 | D14: 195.12506 | E14: 272.73928 | F14: 76.06894 | G14: 105.92645 | H14: 154.66259 | I14: 217.87078 | J14: 0 | K14: 0 | L14: 0 | M14: 0 | N14: 0 | O14: 0 | P14: 0 | Q14: 0
... A23: 20 | B23: 113.63339 | C23: 181.81815 | D23: 312.14176 | E23: 521.88639 | F23: 76.640095 | G23: 120.42601 | H23: 208.10231 | I23: 346.57529 | J23: 0 | K23: 0 | L23: 0 | M23: 0 | N23: 0 | O23: 0 | P23: 0 | Q23: 0

Sheet ws_4
B1: nominal | C1: nominal | D1: nominal | E1: nominal | F1: real | G1: real | H1: real | I1: real | J1: net_flows | K1: net_flows | L1: net_flows | M1: net_flows | N1: real_net_flows | O1: real_net_flows | P1: real_net_flows | Q1: real_net_flows
B2: 1st %ile | C2: 10th %ile | D2: 50th %ile | E2: 90th %ile | F2: 1st %ile | G2: 10th %ile | H2: 50th %ile | I2: 90th %ile | J2: 1st %ile | K2: 10th %ile | L2: 50th %ile | M2: 90th %ile | N2: 1st %ile | O2: 10th %ile | P2: 50th %ile | Q2: 90th %ile
A3: 0 | B3: 100 | C3: 100 | D3: 100 | E3: 100 | F3: 100 | G3: 100 | H3: 100 | I3: 100 | J3: 0 | K3: 0 | L3: 0 | M3: 0 | N3: 0 | O3: 0 | P3: 0 | Q3: 0
A4: 1 | B4: 88.267309 | C4: 96.948911 | D4: 107.50063 | E4: 117.60558 | F4: 85.452261 | G4: 94.483815 | H4: 105.16465 | I4: 115.25495 | J4: 0 | K4: 0 | L4: 0 | M4: 0 | N4: 0 | O4: 0 | P4: 0 | Q4: 0
A5: 2 | B5: 88.796073 | C5: 99.504458 | D5: 114.32103 | E5: 129.82667 | F5: 84.037437 | G5: 94.610001 | H5: 109.2568 | I5: 124.45373 | J5: 0 | K5: 0 | L5: 0 | M5: 0 | N5: 0 | O5: 0 | P5: 0 | Q5: 0
A6: 3 | B6: 90.386638 | C6: 103.63704 | D6: 121.49826 | E6: 141.73015 | F6: 83.351464 | G6: 96.389678 | H6: 113.62808 | I6: 133.05022 | J6: 0 | K6: 0 | L6: 0 | M6: 0 | N6: 0 | O6: 0 | P6: 0 | Q6: 0
A7: 4 | B7: 90.506734 | C7: 107.25153 | D7: 129.85408 | E7: 155.52138 | F7: 82.127308 | G7: 97.495387 | H7: 118.84563 | I7: 143.0414 | J7: 0 | K7: 0 | L7: 0 | M7: 0 | N7: 0 | O7: 0 | P7: 0 | Q7: 0
A8: 5 | B8: 92.109995 | C8: 111.65231 | D8: 138.90603 | E8: 170.50785 | F8: 81.695721 | G8: 99.418353 | H8: 124.34037 | I8: 153.39582 | J8: 0 | K8: 0 | L8: 0 | M8: 0 | N8: 0 | O8: 0 | P8: 0 | Q8: 0
A9: 6 | B9: 93.403158 | C9: 116.16947 | D9: 148.1439 | E9: 185.55286 | F9: 81.287003 | G9: 101.17361 | H9: 129.89299 | I9: 163.72442 | J9: 0 | K9: 0 | L9: 0 | M9: 0 | N9: 0 | O9: 0 | P9: 0 | Q9: 0
A10: 7 | B10: 92.929362 | C10: 119.83745 | D10: 157.6291 | E10: 202.41825 | F10: 78.427294 | G10: 102.26961 | H10: 135.42111 | I10: 174.74896 | J10: 0 | K10: 0 | L10: 0 | M10: 0 | N10: 0 | O10: 0 | P10: 0 | Q10: 0
A11: 8 | B11: 93.365811 | C11: 123.57961 | D11: 167.0514 | E11: 219.43918 | F11: 78.78461 | G11: 103.60518 | H11: 140.75613 | I11: 185.77444 | J11: 0 | K11: 0 | L11: 0 | M11: 0 | N11: 0 | O11: 0 | P11: 0 | Q11: 0
A12: 9 | B12: 93.49924 | C12: 126.95558 | D12: 177.09182 | E12: 238.04886 | F12: 76.869163 | G12: 104.2446 | H12: 145.84143 | I12: 197.84717 | J12: 0 | K12: 0 | L12: 0 | M12: 0 | N12: 0 | O12: 0 | P12: 0 | Q12: 0
A13: 10 | B13: 94.616115 | C13: 131.08057 | D13: 186.85834 | E13: 256.45867 | F13: 76.583098 | G13: 105.54342 | H13: 151.06618 | I13: 209.2877 | J13: 0 | K13: 0 | L13: 0 | M13: 0 | N13: 0 | O13: 0 | P13: 0 | Q13: 0
A14: 11 | B14: 95.813655 | C14: 134.95994 | D14: 197.30423 | E14: 276.69158 | F14: 76.268449 | G14: 106.69508 | H14: 156.46593 | I14: 221.24735 | J14: 0 | K14: 0 | L14: 0 | M14: 0 | N14: 0 | O14: 0 | P14: 0 | Q14: 0
... A23: 20 | B23: 114.81858 | C23: 184.77217 | D23: 318.54421 | E23: 534.91037 | F23: 77.238035 | G23: 122.36637 | H23: 212.49797 | I23: 355.66893 | J23: 0 | K23: 0 | L23: 0 | M23: 0 | N23: 0 | O23: 0 | P23: 0 | Q23: 0

Sheet ws_5
B1: nominal | C1: nominal | D1: nominal | E1: nominal | F1: real | G1: real | H1: real | I1: real | J1: net_flows | K1: net_flows | L1: net_flows | M1: net_flows | N1: real_net_flows | O1: real_net_flows | P1: real_net_flows | Q1: real_net_flows
B2: 1st %ile | C2: 10th %ile | D2: 50th %ile | E2: 90th %ile | F2: 1st %ile | G2: 10th %ile | H2: 50th %ile | I2: 90th %ile | J2: 1st %ile | K2: 10th %ile | L2: 50th %ile | M2: 90th %ile | N2: 1st %ile | O2: 10th %ile | P2: 50th %ile | Q2: 90th %ile
A3: 0 | B3: 100 | C3: 100 | D3: 100 | E3: 100 | F3: 100 | G3: 100 | H3: 100 | I3: 100 | J3: 0 | K3: 0 | L3: 0 | M3: 0 | N3: 0 | O3: 0 | P3: 0 | Q3: 0
A4: 1 | B4: 88.218346 | C4: 96.996857 | D4: 107.59723 | E4: 117.88357 | F4: 85.468796 | G4: 94.555394 | H4: 105.24437 | I4: 115.52087 | J4: 0 | K4: 0 | L4: 0 | M4: 0 | N4: 0 | O4: 0 | P4: 0 | Q4: 0
A5: 2 | B5: 88.818457 | C5: 99.593678 | D5: 114.57508 | E5: 130.22184 | F5: 84.112648 | G5: 94.668494 | H5: 109.44553 | I5: 124.82398 | J5: 0 | K5: 0 | L5: 0 | M5: 0 | N5: 0 | O5: 0 | P5: 0 | Q5: 0
A6: 3 | B6: 90.360673 | C6: 103.86786 | D6: 121.8754 | E6: 142.26376 | F6: 83.3704 | G6: 96.585311 | H6: 113.96033 | I6: 133.58937 | J6: 0 | K6: 0 | L6: 0 | M6: 0 | N6: 0 | O6: 0 | P6: 0 | Q6: 0
A7: 4 | B7: 90.713861 | C7: 107.50607 | D7: 130.38354 | E7: 156.40046 | F7: 82.238706 | G7: 97.695265 | H7: 119.2913 | I7: 143.90544 | J7: 0 | K7: 0 | L7: 0 | M7: 0 | N7: 0 | O7: 0 | P7: 0 | Q7: 0
A8: 5 | B8: 92.22568 | C8: 111.99567 | D8: 139.61676 | E8: 171.7283 | F8: 81.715424 | G8: 99.683273 | H8: 124.98051 | I8: 154.47079 | J8: 0 | K8: 0 | L8: 0 | M8: 0 | N8: 0 | O8: 0 | P8: 0 | Q8: 0
A9: 6 | B9: 93.524376 | C9: 116.52874 | D9: 149.08161 | E9: 187.21035 | F9: 81.304219 | G9: 101.56418 | H9: 130.73314 | I9: 165.06367 | J9: 0 | K9: 0 | L9: 0 | M9: 0 | N9: 0 | O9: 0 | P9: 0 | Q9: 0
A10: 7 | B10: 92.93756 | C10: 120.49153 | D10: 158.73796 | E10: 204.37725 | F10: 78.747267 | G10: 102.77848 | H10: 136.33014 | I10: 176.4345 | J10: 0 | K10: 0 | L10: 0 | M10: 0 | N10: 0 | O10: 0 | P10: 0 | Q10: 0
A11: 8 | B11: 93.261787 | C11: 124.12572 | D11: 168.45924 | E11: 221.83001 | F11: 78.74128 | G11: 104.05332 | H11: 141.92644 | I11: 187.7671 | J11: 0 | K11: 0 | L11: 0 | M11: 0 | N11: 0 | O11: 0 | P11: 0 | Q11: 0
A12: 9 | B12: 93.577081 | C12: 127.63649 | D12: 178.6517 | E12: 241.23751 | F12: 77.100195 | G12: 104.78108 | H12: 147.08018 | I12: 200.30174 | J12: 0 | K12: 0 | L12: 0 | M12: 0 | N12: 0 | O12: 0 | P12: 0 | Q12: 0
A13: 10 | B13: 94.605517 | C13: 131.90469 | D13: 188.80034 | E13: 260.17119 | F13: 76.910687 | G13: 106.14707 | H13: 152.53622 | I13: 212.27918 | J13: 0 | K13: 0 | L13: 0 | M13: 0 | N13: 0 | O13: 0 | P13: 0 | Q13: 0
A14: 11 | B14: 95.787016 | C14: 135.77495 | D14: 199.48447 | E14: 280.53379 | F14: 76.653606 | G14: 107.51019 | H14: 158.06885 | I14: 224.39689 | J14: 0 | K14: 0 | L14: 0 | M14: 0 | N14: 0 | O14: 0 | P14: 0 | Q14: 0
... A23: 20 | B23: 115.6281 | C23: 187.10556 | D23: 324.94869 | E23: 549.07173 | F23: 78.215309 | G23: 123.88769 | H23: 216.75377 | I23: 364.38504 | J23: 0 | K23: 0 | L23: 0 | M23: 0 | N23: 0 | O23: 0 | P23: 0 | Q23: 0

Sheet ws_6
B1: nominal | C1: nominal | D1: nominal | E1: nominal | F1: real | G1: real | H1: real | I1: real | J1: net_flows | K1: net_flows | L1: net_flows | M1: net_flows | N1: real_net_flows | O1: real_net_flows | P1: real_net_flows | Q1: real_net_flows
B2: 1st %ile | C2: 10th %ile | D2: 50th %ile | E2: 90th %ile | F2: 1st %ile | G2: 10th %ile | H2: 50th %ile | I2: 90th %ile | J2: 1st %ile | K2: 10th %ile | L2: 50th %ile | M2: 90th %ile | N2: 1st %ile | O2: 10th %ile | P2: 50th %ile | Q2: 90th %ile
A3: 0 | B3: 100 | C3: 100 | D3: 100 | E3: 100 | F3: 100 | G3: 100 | H3: 100 | I3: 100 | J3: 0 | K3: 0 | L3: 0 | M3: 0 | N3: 0 | O3: 0 | P3: 0 | Q3: 0
A4: 1 | B4: 88.164365 | C4: 96.985063 | D4: 107.66746 | E4: 118.11067 | F4: 85.391512 | G4: 94.577213 | H4: 105.28692 | I4: 115.75639 | J4: 0 | K4: 0 | L4: 0 | M4: 0 | N4: 0 | O4: 0 | P4: 0 | Q4: 0
A5: 2 | B5: 88.844252 | C5: 99.599107 | D5: 114.77007 | E5: 130.64119 | F5: 84.12422 | G5: 94.693538 | H5: 109.64919 | I5: 125.14153 | J5: 0 | K5: 0 | L5: 0 | M5: 0 | N5: 0 | O5: 0 | P5: 0 | Q5: 0
A6: 3 | B6: 90.414677 | C6: 104.01614 | D6: 122.18792 | E6: 142.81231 | F6: 83.411538 | G6: 96.666773 | H6: 114.249 | I6: 133.99989 | J6: 0 | K6: 0 | L6: 0 | M6: 0 | N6: 0 | O6: 0 | P6: 0 | Q6: 0
A7: 4 | B7: 90.60263 | C7: 107.5883 | D7: 130.83414 | E7: 157.18933 | F7: 82.105513 | G7: 97.872804 | H7: 119.71574 | I7: 144.58505 | J7: 0 | K7: 0 | L7: 0 | M7: 0 | N7: 0 | O7: 0 | P7: 0 | Q7: 0
A8: 5 | B8: 92.081744 | C8: 112.28346 | D8: 140.19976 | E8: 172.77676 | F8: 81.732349 | G8: 99.820254 | H8: 125.51417 | I8: 155.42129 | J8: 0 | K8: 0 | L8: 0 | M8: 0 | N8: 0 | O8: 0 | P8: 0 | Q8: 0
A9: 6 | B9: 93.254983 | C9: 116.76665 | D9: 149.89083 | E9: 188.53052 | F9: 81.18344 | G9: 101.7722 | H9: 131.45185 | I9: 166.25435 | J9: 0 | K9: 0 | L9: 0 | M9: 0 | N9: 0 | O9: 0 | P9: 0 | Q9: 0
A10: 7 | B10: 92.523527 | C10: 120.82294 | D10: 159.62261 | E10: 206.10032 | F10: 78.811595 | G10: 102.99423 | H10: 137.12111 | I10: 177.98158 | J10: 0 | K10: 0 | L10: 0 | M10: 0 | N10: 0 | O10: 0 | P10: 0 | Q10: 0
A11: 8 | B11: 92.99018 | C11: 124.47719 | D11: 169.65132 | E11: 224.00617 | F11: 78.532937 | G11: 104.29118 | H11: 142.91758 | I11: 189.61778 | J11: 0 | K11: 0 | L11: 0 | M11: 0 | N11: 0 | O11: 0 | P11: 0 | Q11: 0
A12: 9 | B12: 93.503594 | C12: 128.12415 | D12: 179.96906 | E12: 244.12909 | F12: 77.094086 | G12: 105.17328 | H12: 148.15713 | I12: 202.7034 | J12: 0 | K12: 0 | L12: 0 | M12: 0 | N12: 0 | O12: 0 | P12: 0 | Q12: 0
A13: 10 | B13: 94.327511 | C13: 132.36895 | D13: 190.31769 | E13: 263.65744 | F13: 76.847977 | G13: 106.53533 | H13: 153.87162 | I13: 214.91663 | J13: 0 | K13: 0 | L13: 0 | M13: 0 | N13: 0 | O13: 0 | P13: 0 | Q13: 0
A14: 11 | B14: 95.754357 | C14: 136.4261 | D14: 201.30957 | E14: 284.40731 | F14: 76.345422 | G14: 107.96632 | H14: 159.47395 | I14: 227.58201 | J14: 0 | K14: 0 | L14: 0 | M14: 0 | N14: 0 | O14: 0 | P14: 0 | Q14: 0
... A23: 20 | B23: 115.71505 | C23: 188.85487 | D23: 330.31484 | E23: 561.15695 | F23: 78.317712 | G23: 124.97994 | H23: 220.36432 | I23: 372.62845 | J23: 0 | K23: 0 | L23: 0 | M23: 0 | N23: 0 | O23: 0 | P23: 0 | Q23: 0

Sheet ws_7
B1: nominal | C1: nominal | D1: nominal | E1: nominal | F1: real | G1: real | H1: real | I1: real | J1: net_flows | K1: net_flows | L1: net_flows | M1: net_flows | N1: real_net_flows | O1: real_net_flows | P1: real_net_flows | Q1: real_net_flows
B2: 1st %ile | C2: 10th %ile | D2: 50th %ile | E2: 90th %ile | F2: 1st %ile | G2: 10th %ile | H2: 50th %ile | I2: 90th %ile | J2: 1st %ile | K2: 10th %ile | L2: 50th %ile | M2: 90th %ile | N2: 1st %ile | O2: 10th %ile | P2: 50th %ile | Q2: 90th %ile
A3: 0 | B3: 100 | C3: 100 | D3: 100 | E3: 100 | F3: 100 | G3: 100 | H3: 100 | I3: 100 | J3: 0 | K3: 0 | L3: 0 | M3: 0 | N3: 0 | O3: 0 | P3: 0 | Q3: 0
A4: 1 | B4: 88.071763 | C4: 96.970641 | D4: 107.73083 | E4: 118.34097 | F4: 85.299508 | G4: 94.558214 | H4: 105.31236 | I4: 115.99672 | J4: 0 | K4: 0 | L4: 0 | M4: 0 | N4: 0 | O4: 0 | P4: 0 | Q4: 0
A5: 2 | B5: 88.803358 | C5: 99.572204 | D5: 114.93946 | E5: 130.94721 | F5: 84.015856 | G5: 94.699595 | H5: 109.81674 | I5: 125.50475 | J5: 0 | K5: 0 | L5: 0 | M5: 0 | N5: 0 | O5: 0 | P5: 0 | Q5: 0
A6: 3 | B6: 90.386857 | C6: 104.03952 | D6: 122.42489 | E6: 143.27651 | F6: 83.432859 | G6: 96.698289 | H6: 114.45865 | I6: 134.46772 | J6: 0 | K6: 0 | L6: 0 | M6: 0 | N6: 0 | O6: 0 | P6: 0 | Q6: 0
A7: 4 | B7: 90.39185 | C7: 107.64455 | D7: 131.18739 | E7: 157.89066 | F7: 82.007795 | G7: 97.861117 | H7: 120.01153 | I7: 145.23564 | J7: 0 | K7: 0 | L7: 0 | M7: 0 | N7: 0 | O7: 0 | P7: 0 | Q7: 0
A8: 5 | B8: 91.923943 | C8: 112.38864 | D8: 140.67839 | E8: 173.65829 | F8: 81.550586 | G8: 99.960647 | H8: 125.95973 | I8: 156.32373 | J8: 0 | K8: 0 | L8: 0 | M8: 0 | N8: 0 | O8: 0 | P8: 0 | Q8: 0
A9: 6 | B9: 93.058438 | C9: 116.94714 | D9: 150.46626 | E9: 189.7276 | F9: 81.102389 | G9: 101.92142 | H9: 131.9178 | I9: 167.32219 | J9: 0 | K9: 0 | L9: 0 | M9: 0 | N9: 0 | O9: 0 | P9: 0 | Q9: 0
A10: 7 | B10: 92.161758 | C10: 121.05171 | D10: 160.34259 | E10: 207.70885 | F10: 78.763426 | G10: 103.14869 | H10: 137.66443 | I10: 179.40459 | J10: 0 | K10: 0 | L10: 0 | M10: 0 | N10: 0 | O10: 0 | P10: 0 | Q10: 0
A11: 8 | B11: 92.943511 | C11: 124.6767 | D11: 170.57917 | E11: 225.96809 | F11: 78.279585 | G11: 104.49625 | H11: 143.66987 | I11: 191.13545 | J11: 0 | K11: 0 | L11: 0 | M11: 0 | N11: 0 | O11: 0 | P11: 0 | Q11: 0
A12: 9 | B12: 93.143318 | C12: 128.31503 | D12: 181.04385 | E12: 246.31662 | F12: 77.045191 | G12: 105.30648 | H12: 149.02328 | I12: 204.65668 | J12: 0 | K12: 0 | L12: 0 | M12: 0 | N12: 0 | O12: 0 | P12: 0 | Q12: 0
A13: 10 | B13: 93.993341 | C13: 132.64426 | D13: 191.62668 | E13: 266.4406 | F13: 76.415707 | G13: 106.7807 | H13: 154.88077 | I13: 217.3476 | J13: 0 | K13: 0 | L13: 0 | M13: 0 | N13: 0 | O13: 0 | P13: 0 | Q13: 0
A14: 11 | B14: 95.692478 | C14: 136.89089 | D14: 202.76776 | E14: 287.89854 | F14: 76.109509 | G14: 108.20496 | H14: 160.59238 | I14: 230.13153 | J14: 0 | K14: 0 | L14: 0 | M14: 0 | N14: 0 | O14: 0 | P14: 0 | Q14: 0
... A23: 20 | B23: 115.48763 | C23: 189.71247 | D23: 334.96301 | E23: 572.44786 | F23: 78.304305 | G23: 125.70012 | H23: 223.16957 | I23: 380.33123 | J23: 0 | K23: 0 | L23: 0 | M23: 0 | N23: 0 | O23: 0 | P23: 0 | Q23: 0

Sheet ws_8
B1: nominal | C1: nominal | D1: nominal | E1: nominal | F1: real | G1: real | H1: real | I1: real | J1: net_flows | K1: net_flows | L1: net_flows | M1: net_flows | N1: real_net_flows | O1: real_net_flows | P1: real_net_flows | Q1: real_net_flows
B2: 1st %ile | C2: 10th %ile | D2: 50th %ile | E2: 90th %ile | F2: 1st %ile | G2: 10th %ile | H2: 50th %ile | I2: 90th %ile | J2: 1st %ile | K2: 10th %ile | L2: 50th %ile | M2: 90th %ile | N2: 1st %ile | O2: 10th %ile | P2: 50th %ile | Q2: 90th %ile
A3: 0 | B3: 100 | C3: 100 | D3: 100 | E3: 100 | F3: 100 | G3: 100 | H3: 100 | I3: 100 | J3: 0 | K3: 0 | L3: 0 | M3: 0 | N3: 0 | O3: 0 | P3: 0 | Q3: 0
A4: 1 | B4: 87.988618 | C4: 96.943585 | D4: 107.74998 | E4: 118.54525 | F4: 85.188918 | G4: 94.531205 | H4: 105.35267 | I4: 116.15381 | J4: 0 | K4: 0 | L4: 0 | M4: 0 | N4: 0 | O4: 0 | P4: 0 | Q4: 0
A5: 2 | B5: 88.72057 | C5: 99.560352 | D5: 115.06325 | E5: 131.20737 | F5: 83.9266 | G5: 94.676211 | H5: 109.93118 | I5: 125.73335 | J5: 0 | K5: 0 | L5: 0 | M5: 0 | N5: 0 | O5: 0 | P5: 0 | Q5: 0
A6: 3 | B6: 90.295108 | C6: 104.01976 | D6: 122.59403 | E6: 143.66428 | F6: 83.318125 | G6: 96.698785 | H6: 114.59897 | I6: 134.80048 | J6: 0 | K6: 0 | L6: 0 | M6: 0 | N6: 0 | O6: 0 | P6: 0 | Q6: 0
A7: 4 | B7: 90.242136 | C7: 107.65874 | D7: 131.42726 | E7: 158.45964 | F7: 81.848994 | G7: 97.860342 | H7: 120.25941 | I7: 145.73686 | J7: 0 | K7: 0 | L7: 0 | M7: 0 | N7: 0 | O7: 0 | P7: 0 | Q7: 0
A8: 5 | B8: 91.671296 | C8: 112.40227 | D8: 141.00137 | E8: 174.38497 | F8: 81.328363 | G8: 99.993213 | H8: 126.23746 | I8: 157.01527 | J8: 0 | K8: 0 | L8: 0 | M8: 0 | N8: 0 | O8: 0 | P8: 0 | Q8: 0
A9: 6 | B9: 92.795483 | C9: 116.97484 | D9: 150.87256 | E9: 190.71428 | F9: 81.002205 | G9: 101.98149 | H9: 132.29291 | I9: 168.17763 | J9: 0 | K9: 0 | L9: 0 | M9: 0 | N9: 0 | O9: 0 | P9: 0 | Q9: 0
A10: 7 | B10: 91.91447 | C10: 121.10152 | D10: 160.89754 | E10: 208.98987 | F10: 78.652422 | G10: 103.17422 | H10: 138.15777 | I10: 180.49078 | J10: 0 | K10: 0 | L10: 0 | M10: 0 | N10: 0 | O10: 0 | P10: 0 | Q10: 0
A11: 8 | B11: 92.854333 | C11: 124.76016 | D11: 171.17481 | E11: 227.5249 | F11: 77.932385 | G11: 104.54625 | H11: 144.26621 | I11: 192.50576 | J11: 0 | K11: 0 | L11: 0 | M11: 0 | N11: 0 | O11: 0 | P11: 0 | Q11: 0
A12: 9 | B12: 92.82956 | C12: 128.55635 | D12: 181.70845 | E12: 248.19031 | F12: 77.000554 | G12: 105.37275 | H12: 149.74341 | I12: 206.07597 | J12: 0 | K12: 0 | L12: 0 | M12: 0 | N12: 0 | O12: 0 | P12: 0 | Q12: 0
A13: 10 | B13: 93.859636 | C13: 132.73571 | D13: 192.55304 | E13: 268.64637 | F13: 76.128781 | G13: 106.96919 | H13: 155.67199 | I13: 219.0594 | J13: 0 | K13: 0 | L13: 0 | M13: 0 | N13: 0 | O13: 0 | P13: 0 | Q13: 0
A14: 11 | B14: 95.3112 | C14: 136.93303 | D14: 203.96941 | E14: 290.51545 | F14: 75.945411 | G14: 108.43237 | H14: 161.47699 | I14: 232.25708 | J14: 0 | K14: 0 | L14: 0 | M14: 0 | N14: 0 | O14: 0 | P14: 0 | Q14: 0
... A23: 20 | B23: 115.0875 | C23: 190.84067 | D23: 338.31976 | E23: 580.56245 | F23: 78.171304 | G23: 126.47619 | H23: 225.69831 | I23: 385.91701 | J23: 0 | K23: 0 | L23: 0 | M23: 0 | N23: 0 | O23: 0 | P23: 0 | Q23: 0

Sheet ws_9
B1: nominal | C1: nominal | D1: nominal | E1: nominal | F1: real | G1: real | H1: real | I1: real | J1: net_flows | K1: net_flows | L1: net_flows | M1: net_flows | N1: real_net_flows | O1: real_net_flows | P1: real_net_flows | Q1: real_net_flows
B2: 1st %ile | C2: 10th %ile | D2: 50th %ile | E2: 90th %ile | F2: 1st %ile | G2: 10th %ile | H2: 50th %ile | I2: 90th %ile | J2: 1st %ile | K2: 10th %ile | L2: 50th %ile | M2: 90th %ile | N2: 1st %ile | O2: 10th %ile | P2: 50th %ile | Q2: 90th %ile
A3: 0 | B3: 100 | C3: 100 | D3: 100 | E3: 100 | F3: 100 | G3: 100 | H3: 100 | I3: 100 | J3: 0 | K3: 0 | L3: 0 | M3: 0 | N3: 0 | O3: 0 | P3: 0 | Q3: 0
A4: 1 | B4: 87.948661 | C4: 96.923637 | D4: 107.76596 | E4: 118.64351 | F4: 85.101003 | G4: 94.517154 | H4: 105.36917 | I4: 116.27289 | J4: 0 | K4: 0 | L4: 0 | M4: 0 | N4: 0 | O4: 0 | P4: 0 | Q4: 0
A5: 2 | B5: 88.712227 | C5: 99.551197 | D5: 115.11341 | E5: 131.35797 | F5: 83.820599 | G5: 94.667981 | H5: 109.99757 | I5: 125.86922 | J5: 0 | K5: 0 | L5: 0 | M5: 0 | N5: 0 | O5: 0 | P5: 0 | Q5: 0
A6: 3 | B6: 90.312734 | C6: 104.01214 | D6: 122.69969 | E6: 143.85614 | F6: 83.252756 | G6: 96.696324 | H6: 114.70799 | I6: 135.0209 | J6: 0 | K6: 0 | L6: 0 | M6: 0 | N6: 0 | O6: 0 | P6: 0 | Q6: 0
A7: 4 | B7: 90.126712 | C7: 107.69327 | D7: 131.61217 | E7: 158.87256 | F7: 81.710955 | G7: 97.831371 | H7: 120.42917 | I7: 146.04932 | J7: 0 | K7: 0 | L7: 0 | M7: 0 | N7: 0 | O7: 0 | P7: 0 | Q7: 0
A8: 5 | B8: 91.522416 | C8: 112.39964 | D8: 141.20959 | E8: 174.83069 | F8: 81.244559 | G8: 99.990598 | H8: 126.44341 | I8: 157.49583 | J8: 0 | K8: 0 | L8: 0 | M8: 0 | N8: 0 | O8: 0 | P8: 0 | Q8: 0
A9: 6 | B9: 92.737366 | C9: 117.01937 | D9: 151.13604 | E9: 191.32556 | F9: 80.856079 | G9: 101.9997 | H9: 132.518 | I9: 168.76568 | J9: 0 | K9: 0 | L9: 0 | M9: 0 | N9: 0 | O9: 0 | P9: 0 | Q9: 0
A10: 7 | B10: 91.71029 | C10: 121.15612 | D10: 161.23986 | E10: 209.84391 | F10: 78.620731 | G10: 103.24458 | H10: 138.42248 | I10: 181.16947 | J10: 0 | K10: 0 | L10: 0 | M10: 0 | N10: 0 | O10: 0 | P10: 0 | Q10: 0
A11: 8 | B11: 92.651441 | C11: 124.81827 | D11: 171.57175 | E11: 228.48873 | F11: 77.782658 | G11: 104.58165 | H11: 144.61178 | I11: 193.39529 | J11: 0 | K11: 0 | L11: 0 | M11: 0 | N11: 0 | O11: 0 | P11: 0 | Q11: 0
A12: 9 | B12: 92.644107 | C12: 128.60066 | D12: 182.14617 | E12: 249.44861 | F12: 76.840853 | G12: 105.44079 | H12: 150.14265 | I12: 207.03068 | J12: 0 | K12: 0 | L12: 0 | M12: 0 | N12: 0 | O12: 0 | P12: 0 | Q12: 0
A13: 10 | B13: 93.799667 | C13: 132.7239 | D13: 193.07426 | E13: 270.02023 | F13: 76.059734 | G13: 107.04197 | H13: 156.11085 | I13: 220.31863 | J13: 0 | K13: 0 | L13: 0 | M13: 0 | N13: 0 | O13: 0 | P13: 0 | Q13: 0
A14: 11 | B14: 94.985572 | C14: 137.01181 | D14: 204.65346 | E14: 292.2204 | F14: 75.694658 | G14: 108.53525 | H14: 162.01545 | I14: 233.52441 | J14: 0 | K14: 0 | L14: 0 | M14: 0 | N14: 0 | O14: 0 | P14: 0 | Q14: 0
... A23: 20 | B23: 114.78014 | C23: 191.18626 | D23: 340.44774 | E23: 585.59647 | F23: 78.25006 | G23: 126.85185 | H23: 227.15529 | I23: 389.27541 | J23: 0 | K23: 0 | L23: 0 | M23: 0 | N23: 0 | O23: 0 | P23: 0 | Q23: 0

Sheet ws_10
B1: nominal | C1: nominal | D1: nominal | E1: nominal | F1: real | G1: real | H1: real | I1: real | J1: net_flows | K1: net_flows | L1: net_flows | M1: net_flows | N1: real_net_flows | O1: real_net_flows | P1: real_net_flows | Q1: real_net_flows
B2: 1st %ile | C2: 10th %ile | D2: 50th %ile | E2: 90th %ile | F2: 1st %ile | G2: 10th %ile | H2: 50th %ile | I2: 90th %ile | J2: 1st %ile | K2: 10th %ile | L2: 50th %ile | M2: 90th %ile | N2: 1st %ile | O2: 10th %ile | P2: 50th %ile | Q2: 90th %ile
A3: 0 | B3: 100 | C3: 100 | D3: 100 | E3: 100 | F3: 100 | G3: 100 | H3: 100 | I3: 100 | J3: 0 | K3: 0 | L3: 0 | M3: 0 | N3: 0 | O3: 0 | P3: 0 | Q3: 0
A4: 1 | B4: 87.91084 | C4: 96.913768 | D4: 107.77632 | E4: 118.69311 | F4: 85.071529 | G4: 94.502 | H4: 105.38454 | I4: 116.31243 | J4: 0 | K4: 0 | L4: 0 | M4: 0 | N4: 0 | O4: 0 | P4: 0 | Q4: 0
A5: 2 | B5: 88.665669 | C5: 99.530227 | D5: 115.13201 | E5: 131.4191 | F5: 83.787492 | G5: 94.659829 | H5: 110.03072 | I5: 125.92948 | J5: 0 | K5: 0 | L5: 0 | M5: 0 | N5: 0 | O5: 0 | P5: 0 | Q5: 0
A6: 3 | B6: 90.285479 | C6: 103.98963 | D6: 122.72735 | E6: 143.95489 | F6: 83.229136 | G6: 96.682004 | H6: 114.7506 | I6: 135.13515 | J6: 0 | K6: 0 | L6: 0 | M6: 0 | N6: 0 | O6: 0 | P6: 0 | Q6: 0
A7: 4 | B7: 90.081348 | C7: 107.68184 | D7: 131.65545 | E7: 159.05178 | F7: 81.642346 | G7: 97.834796 | H7: 120.49066 | I7: 146.15763 | J7: 0 | K7: 0 | L7: 0 | M7: 0 | N7: 0 | O7: 0 | P7: 0 | Q7: 0
A8: 5 | B8: 91.469319 | C8: 112.40278 | D8: 141.30486 | E8: 175.02767 | F8: 81.141211 | G8: 99.9741 | H8: 126.50866 | I8: 157.70142 | J8: 0 | K8: 0 | L8: 0 | M8: 0 | N8: 0 | O8: 0 | P8: 0 | Q8: 0
